Workbook

Sheet JAN
B1: PELADA DA RESENHA - TERÇA 20H
B3: JOGADOR | C3: 45664 | H3: =C3+7 -> 45671 | M3: =H3+7 -> 45678 | R3: =M3+7 -> 45685 | W3: - | AB3: PRESENÇA | AC3: GOLS TOTAIS | AD3: ASSIST TOTAIS | AE3: G+A | AF3: FOTOS | AG3: MÉDIA TOTAL
C4: PRESENTE | D4: GOL | E4: ASSIST | F4: NOTA | H4: PRESENTE | I4: GOL | J4: ASSIST | K4: NOTA | M4: PRESENTE | N4: GOL | O4: ASSIST | P4: NOTA | R4: PRESENTE | S4: GOL | T4: ASSIST | U4: NOTA | W4: PRESENTE | X4: GOL | Y4: ASSIST | Z4: NOTA
B5: Alberto Henrique | H5: P | I5: 3 | J5: 2 | K5: 7.38 | M5: P | N5: 2 | O5: 0 | P5: 6.06 | R5: P | S5: 1 | T5: 0 | U5: 5.26 | AB5: =COUNTIF(C5:Z5,"P") -> 3 | AC5: =SUM(D5,I5,N5,S5,X5) -> 6 | AD5: =SUM(E5,J5,O5,T5,Y5) -> 2 | AE5: =SUM(AC5+AD5) -> 8 | AF5: =COUNTIF(G5:AA5,"F") -> 0 | AG5: =IFERROR(AVERAGE(F5,K5,P5,U5,Z5),"-") -> 6.2333333
B6: Allan Borela | C6: P | D6: 0 | E6: 0 | G6: F | H6: P | I6: 0 | J6: 1 | K6: 4.2 | M6: P | N6: 1 | O6: 0 | P6: 5.88 | Q6: F | R6: P | S6: 0 | T6: 1 | U6: 4.64 | AB6: =COUNTIF(C6:Z6,"P") -> 4 | AC6: =SUM(D6,I6,N6,S6,X6) -> 1 | AD6: =SUM(E6,J6,O6,T6,Y6) -> 2 | AE6: =SUM(AC6+AD6) -> 3 | AF6: =COUNTIF(G6:AA6,"F") -> 2 | AG6: =IFERROR(AVERAGE(F6,K6,P6,U6,Z6),"-") -> 4.9066667
B7: Breno (GK) | AB7: =COUNTIF(C7:Z7,"P") -> 0 | AC7: =SUM(D7,I7,N7,S7,X7) -> 0 | AD7: =SUM(E7,J7,O7,T7,Y7) -> 0 | AE7: =SUM(AC7+AD7) -> 0 | AF7: =COUNTIF(G7:AA7,"F") -> 0 | AG7: =IFERROR(AVERAGE(F7,K7,P7,U7,Z7),"-") -> -
B8: Daniel Medeiros (GK) | AB8: =COUNTIF(C8:Z8,"P") -> 0 | AC8: =SUM(D8,I8,N8,S8,X8) -> 0 | AD8: =SUM(E8,J8,O8,T8,Y8) -> 0 | AE8: =SUM(AC8+AD8) -> 0 | AF8: =COUNTIF(G8:AA8,"F") -> 0 | AG8: =IFERROR(AVERAGE(F8,K8,P8,U8,Z8),"-") -> -
B9: David Melo | AB9: =COUNTIF(C9:Z9,"P") -> 0 | AC9: =SUM(D9,I9,N9,S9,X9) -> 0 | AD9: =SUM(E9,J9,O9,T9,Y9) -> 0 | AE9: =SUM(AC9+AD9) -> 0 | AF9: =COUNTIF(G9:AA9,"F") -> 0 | AG9: =IFERROR(AVERAGE(F9,K9,P9,U9,Z9),"-") -> -
B10: Douglas DG (GK) | C10: P | D10: 0 | E10: 0 | G10: F | H10: P | I10: 0 | J10: 0 | K10: 7.04 | L10: F | M10: P | N10: 0 | O10: 0 | P10: 6.94 | Q10: F | R10: P | S10: 0 | T10: 0 | U10: 7.78 | V10: F | AB10: =COUNTIF(C10:Z10,"P") -> 4 | AC10: =SUM(D10,I10,N10,S10,X10) -> 0 | AD10: =SUM(E10,J10,O10,T10,Y10) -> 0 | AE10: =SUM(AC10+AD10) -> 0 | AF10: =COUNTIF(G10:AA10,"F") -> 4 | AG10: =IFERROR(AVERAGE(F10,K10,P10,U10,Z10),"-") -> 7.2533333
B11: Felipe Horsts | AB11: =COUNTIF(C11:Z11,"P") -> 0 | AC11: =SUM(D11,I11,N11,S11,X11) -> 0 | AD11: =SUM(E11,J11,O11,T11,Y11) -> 0 | AE11: =SUM(AC11+AD11) -> 0 | AF11: =COUNTIF(G11:AA11,"F") -> 0 | AG11: =IFERROR(AVERAGE(F11,K11,P11,U11,Z11),"-") -> -
B12: Gabriel Andrade | H12: P | I12: 1 | J12: 1 | K12: 5.88 | R12: P | S12: 1 | T12: 2 | U12: 6.9 | V12: F | AB12: =COUNTIF(C12:Z12,"P") -> 2 | AC12: =SUM(D12,I12,N12,S12,X12) -> 2 | AD12: =SUM(E12,J12,O12,T12,Y12) -> 3 | AE12: =SUM(AC12+AD12) -> 5 | AF12: =COUNTIF(G12:AA12,"F") -> 1 | AG12: =IFERROR(AVERAGE(F12,K12,P12,U12,Z12),"-") -> 6.39
B13: Gabriel Castro | C13: P | D13: 2 | E13: 0 | H13: P | I13: 0 | J13: 0 | K13: 4.46 | R13: P | S13: 0 | T13: 2 | U13: 4.22 | AB13: =COUNTIF(C13:Z13,"P") -> 3 | AC13: =SUM(D13,I13,N13,S13,X13) -> 2 | AD13: =SUM(E13,J13,O13,T13,Y13) -> 2 | AE13: =SUM(AC13+AD13) -> 4 | AF13: =COUNTIF(G13:AA13,"F") -> 0 | AG13: =IFERROR(AVERAGE(F13,K13,P13,U13,Z13),"-") -> 4.34
B14: Gabriel Cosendey | H14: P | I14: 0 | J14: 2 | K14: 7.16 | L14: F | AB14: =COUNTIF(C14:Z14,"P") -> 1 | AC14: =SUM(D14,I14,N14,S14,X14) -> 0 | AD14: =SUM(E14,J14,O14,T14,Y14) -> 2 | AE14: =SUM(AC14+AD14) -> 2 | AF14: =COUNTIF(G14:AA14,"F") -> 1 | AG14: =IFERROR(AVERAGE(F14,K14,P14,U14,Z14),"-") -> 7.16
B15: Gabriel Teixeira | AB15: =COUNTIF(C15:Z15,"P") -> 0 | AC15: =SUM(D15,I15,N15,S15,X15) -> 0 | AD15: =SUM(E15,J15,O15,T15,Y15) -> 0 | AE15: =SUM(AC15+AD15) -> 0 | AF15: =COUNTIF(G15:AA15,"F") -> 0 | AG15: =IFERROR(AVERAGE(F15,K15,P15,U15,Z15),"-") -> -
B16: Guilherme Santos (GK) | C16: P | D16: 0 | E16: 0 | H16: P | I16: 0 | J16: 0 | K16: 6.3 | M16: P | N16: 0 | O16: 0 | P16: 5.22 | R16: P | S16: 0 | T16: 0 | U16: 5 | AB16: =COUNTIF(C16:Z16,"P") -> 4 | AC16: =SUM(D16,I16,N16,S16,X16) -> 0 | AD16: =SUM(E16,J16,O16,T16,Y16) -> 0 | AE16: =SUM(AC16+AD16) -> 0 | AF16: =COUNTIF(G16:AA16,"F") -> 0 | AG16: =IFERROR(AVERAGE(F16,K16,P16,U16,Z16),"-") -> 5.5066667
B17: Gustavo Bumbum (GK) | AB17: =COUNTIF(C17:Z17,"P") -> 0 | AC17: =SUM(D17,I17,N17,S17,X17) -> 0 | AD17: =SUM(E17,J17,O17,T17,Y17) -> 0 | AE17: =SUM(AC17+AD17) -> 0 | AF17: =COUNTIF(G17:AA17,"F") -> 0 | AG17: =IFERROR(AVERAGE(F17,K17,P17,U17,Z17),"-") -> -
B18: Gustavo Gomes | C18: P | D18: 1 | E18: 0 | H18: P | I18: 2 | J18: 0 | K18: 4.12 | R18: P | S18: 0 | T18: 1 | U18: 4.16 | AB18: =COUNTIF(C18:Z18,"P") -> 3 | AC18: =SUM(D18,I18,N18,S18,X18) -> 3 | AD18: =SUM(E18,J18,O18,T18,Y18) -> 1 | AE18: =SUM(AC18+AD18) -> 4 | AF18: =COUNTIF(G18:AA18,"F") -> 0 | AG18: =IFERROR(AVERAGE(F18,K18,P18,U18,Z18),"-") -> 4.14
B19: Henrique Viza | H19: P | I19: 2 | J19: 1 | K19: 6.76 | AB19: =COUNTIF(C19:Z19,"P") -> 1 | AC19: =SUM(D19,I19,N19,S19,X19) -> 2 | AD19: =SUM(E19,J19,O19,T19,Y19) -> 1 | AE19: =SUM(AC19+AD19) -> 3 | AF19: =COUNTIF(G19:AA19,"F") -> 0 | AG19: =IFERROR(AVERAGE(F19,K19,P19,U19,Z19),"-") -> 6.76
B20: Jeferson Neves | AB20: =COUNTIF(C20:Z20,"P") -> 0 | AC20: =SUM(D20,I20,N20,S20,X20) -> 0 | AD20: =SUM(E20,J20,O20,T20,Y20) -> 0 | AE20: =SUM(AC20+AD20) -> 0 | AF20: =COUNTIF(G20:AA20,"F") -> 0 | AG20: =IFERROR(AVERAGE(F20,K20,P20,U20,Z20),"-") -> -
B21: João Victor - Bazim | H21: P | I21: 0 | J21: 0 | K21: 4.84 | L21: F | R21: P | S21: 0 | T21: 0 | U21: 5.64 | V21: F | AB21: =COUNTIF(C21:Z21,"P") -> 2 | AC21: =SUM(D21,I21,N21,S21,X21) -> 0 | AD21: =SUM(E21,J21,O21,T21,Y21) -> 0 | AE21: =SUM(AC21+AD21) -> 0 | AF21: =COUNTIF(G21:AA21,"F") -> 2 | AG21: =IFERROR(AVERAGE(F21,K21,P21,U21,Z21),"-") -> 5.24
B22: João Vitor Nunes | C22: P | D22: 2 | E22: 0 | H22: P | I22: 1 | J22: 0 | K22: 4.16 | L22: F | M22: P | N22: 2 | O22: 2 | P22: 5.66 | Q22: F | R22: P | S22: 5 | T22: 2 | U22: 6.06 | V22: F | AB22: =COUNTIF(C22:Z22,"P") -> 4 | AC22: =SUM(D22,I22,N22,S22,X22) -> 10 | AD22: =SUM(E22,J22,O22,T22,Y22) -> 4 | AE22: =SUM(AC22+AD22) -> 14 | AF22: =COUNTIF(G22:AA22,"F") -> 3 | AG22: =IFERROR(AVERAGE(F22,K22,P22,U22,Z22),"-") -> 5.2933333
B23: José Guilherme | AB23: =COUNTIF(C23:Z23,"P") -> 0 | AC23: =SUM(D23,I23,N23,S23,X23) -> 0 | AD23: =SUM(E23,J23,O23,T23,Y23) -> 0 | AE23: =SUM(AC23+AD23) -> 0 | AF23: =COUNTIF(G23:AA23,"F") -> 0 | AG23: =IFERROR(AVERAGE(F23,K23,P23,U23,Z23),"-") -> -
B24: Kyrius Barros | AB24: =COUNTIF(C24:Z24,"P") -> 0 | AC24: =SUM(D24,I24,N24,S24,X24) -> 0 | AD24: =SUM(E24,J24,O24,T24,Y24) -> 0 | AE24: =SUM(AC24+AD24) -> 0 | AF24: =COUNTIF(G24:AA24,"F") -> 0 | AG24: =IFERROR(AVERAGE(F24,K24,P24,U24,Z24),"-") -> -
B25: Leo Bitencourt | AB25: =COUNTIF(C25:Z25,"P") -> 0 | AC25: =SUM(D25,I25,N25,S25,X25) -> 0 | AD25: =SUM(E25,J25,O25,T25,Y25) -> 0 | AE25: =SUM(AC25+AD25) -> 0 | AF25: =COUNTIF(G25:AA25,"F") -> 0 | AG25: =IFERROR(AVERAGE(F25,K25,P25,U25,Z25),"-") -> -
B26: Leo Hubner | AB26: =COUNTIF(C26:Z26,"P") -> 0 | AC26: =SUM(D26,I26,N26,S26,X26) -> 0 | AD26: =SUM(E26,J26,O26,T26,Y26) -> 0 | AE26: =SUM(AC26+AD26) -> 0 | AF26: =COUNTIF(G26:AA26,"F") -> 0 | AG26: =IFERROR(AVERAGE(F26,K26,P26,U26,Z26),"-") -> -
B27: Leo Starling | G27: F | H27: P | I27: 2 | J27: 0 | K27: 6 | M27: P | N27: 1 | O27: 1 | P27: 4.88 | AB27: =COUNTIF(C27:Z27,"P") -> 2 | AC27: =SUM(D27,I27,N27,S27,X27) -> 3 | AD27: =SUM(E27,J27,O27,T27,Y27) -> 1 | AE27: =SUM(AC27+AD27) -> 4 | AF27: =COUNTIF(G27:AA27,"F") -> 1 | AG27: =IFERROR(AVERAGE(F27,K27,P27,U27,Z27),"-") -> 5.44
B28: Lucas Bertolace | AB28: =COUNTIF(C28:Z28,"P") -> 0 | AC28: =SUM(D28,I28,N28,S28,X28) -> 0 | AD28: =SUM(E28,J28,O28,T28,Y28) -> 0 | AE28: =SUM(AC28+AD28) -> 0 | AF28: =COUNTIF(G28:AA28,"F") -> 0 | AG28: =IFERROR(AVERAGE(F28,K28,P28,U28,Z28),"-") -> -
B29: Lucas Borela | AB29: =COUNTIF(C29:Z29,"P") -> 0 | AC29: =SUM(D29,I29,N29,S29,X29) -> 0 | AD29: =SUM(E29,J29,O29,T29,Y29) -> 0 | AE29: =SUM(AC29+AD29) -> 0 | AF29: =COUNTIF(G29:AA29,"F") -> 0 | AG29: =IFERROR(AVERAGE(F29,K29,P29,U29,Z29),"-") -> -
B30: Lucas Gama - Passarim | AB30: =COUNTIF(C30:Z30,"P") -> 0 | AC30: =SUM(D30,I30,N30,S30,X30) -> 0 | AD30: =SUM(E30,J30,O30,T30,Y30) -> 0 | AE30: =SUM(AC30+AD30) -> 0 | AF30: =COUNTIF(G30:AA30,"F") -> 0 | AG30: =IFERROR(AVERAGE(F30,K30,P30,U30,Z30),"-") -> -
B31: Lucas Leite - Coxinha | M31: P | N31: 0 | O31: 1 | P31: 4.28 | AB31: =COUNTIF(C31:Z31,"P") -> 1 | AC31: =SUM(D31,I31,N31,S31,X31) -> 0 | AD31: =SUM(E31,J31,O31,T31,Y31) -> 1 | AE31: =SUM(AC31+AD31) -> 1 | AF31: =COUNTIF(G31:AA31,"F") -> 0 | AG31: =IFERROR(AVERAGE(F31,K31,P31,U31,Z31),"-") -> 4.28
B32: Luis do Corte | AB32: =COUNTIF(C32:Z32,"P") -> 0 | AC32: =SUM(D32,I32,N32,S32,X32) -> 0 | AD32: =SUM(E32,J32,O32,T32,Y32) -> 0 | AE32: =SUM(AC32+AD32) -> 0 | AF32: =COUNTIF(G32:AA32,"F") -> 0 | AG32: =IFERROR(AVERAGE(F32,K32,P32,U32,Z32),"-") -> -
B33: Marcelo Castro | C33: P | D33: 3 | E33: 2 | G33: F | H33: P | I33: 3 | J33: 0 | K33: 7.96 | L33: F | M33: P | N33: 3 | O33: 1 | P33: 8.42 | Q33: F | R33: P | S33: 0 | T33: 1 | U33: 6 | AB33: =COUNTIF(C33:Z33,"P") -> 4 | AC33: =SUM(D33,I33,N33,S33,X33) -> 9 | AD33: =SUM(E33,J33,O33,T33,Y33) -> 4 | AE33: =SUM(AC33+AD33) -> 13 | AF33: =COUNTIF(G33:AA33,"F") -> 3 | AG33: =IFERROR(AVERAGE(F33,K33,P33,U33,Z33),"-") -> 7.46
B34: Marco Antonio | AB34: =COUNTIF(C34:Z34,"P") -> 0 | AC34: =SUM(D34,I34,N34,S34,X34) -> 0 | AD34: =SUM(E34,J34,O34,T34,Y34) -> 0 | AE34: =SUM(AC34+AD34) -> 0 | AF34: =COUNTIF(G34:AA34,"F") -> 0 | AG34: =IFERROR(AVERAGE(F34,K34,P34,U34,Z34),"-") -> -
B35: Matheus Gomes | H35: P | I35: 1 | J35: 1 | K35: 5.54 | M35: P | N35: 0 | O35: 0 | P35: 4.94 | R35: P | S35: 1 | T35: 1 | U35: 4.42 | AB35: =COUNTIF(C35:Z35,"P") -> 3 | AC35: =SUM(D35,I35,N35,S35,X35) -> 2 | AD35: =SUM(E35,J35,O35,T35,Y35) -> 2 | AE35: =SUM(AC35+AD35) -> 4 | AF35: =COUNTIF(G35:AA35,"F") -> 0 | AG35: =IFERROR(AVERAGE(F35,K35,P35,U35,Z35),"-") -> 4.9666667
B36: Meurin | H36: P | I36: 1 | J36: 1 | K36: 5.66 | M36: P | N36: 2 | O36: 3 | P36: 7.22 | Q36: F | AB36: =COUNTIF(C36:Z36,"P") -> 2 | AC36: =SUM(D36,I36,N36,S36,X36) -> 3 | AD36: =SUM(E36,J36,O36,T36,Y36) -> 4 | AE36: =SUM(AC36+AD36) -> 7 | AF36: =COUNTIF(G36:AA36,"F") -> 1 | AG36: =IFERROR(AVERAGE(F36,K36,P36,U36,Z36),"-") -> 6.44
B37: Pablo Brandão | C37: P | D37: 0 | E37: 2 | H37: P | I37: 0 | J37: 0 | K37: 3.88 | M37: P | N37: 0 | O37: 0 | P37: 5.12 | R37: P | S37: 0 | T37: 1 | U37: 5.36 | V37: F | AB37: =COUNTIF(C37:Z37,"P") -> 4 | AC37: =SUM(D37,I37,N37,S37,X37) -> 0 | AD37: =SUM(E37,J37,O37,T37,Y37) -> 3 | AE37: =SUM(AC37+AD37) -> 3 | AF37: =COUNTIF(G37:AA37,"F") -> 1 | AG37: =IFERROR(AVERAGE(F37,K37,P37,U37,Z37),"-") -> 4.7866667
B38: Pedro Abreu | AB38: =COUNTIF(C38:Z38,"P") -> 0 | AC38: =SUM(D38,I38,N38,S38,X38) -> 0 | AD38: =SUM(E38,J38,O38,T38,Y38) -> 0 | AE38: =SUM(AC38+AD38) -> 0 | AF38: =COUNTIF(G38:AA38,"F") -> 0 | AG38: =IFERROR(AVERAGE(F38,K38,P38,U38,Z38),"-") -> -
B39: Pedro Chequer | H39: P | I39: 0 | J39: 0 | K39: 4.88 | M39: P | N39: 1 | O39: 1 | P39: 5.84 | Q39: F | AB39: =COUNTIF(C39:Z39,"P") -> 2 | AC39: =SUM(D39,I39,N39,S39,X39) -> 1 | AD39: =SUM(E39,J39,O39,T39,Y39) -> 1 | AE39: =SUM(AC39+AD39) -> 2 | AF39: =COUNTIF(G39:AA39,"F") -> 1 | AG39: =IFERROR(AVERAGE(F39,K39,P39,U39,Z39),"-") -> 5.36
B40: Pedro Dias | H40: P | I40: 2 | J40: 1 | K40: 6.2 | L40: F | M40: P | N40: 0 | O40: 0 | P40: 5.16 | R40: P | S40: 2 | T40: 2 | U40: 5.64 | V40: F | AB40: =COUNTIF(C40:Z40,"P") -> 3 | AC40: =SUM(D40,I40,N40,S40,X40) -> 4 | AD40: =SUM(E40,J40,O40,T40,Y40) -> 3 | AE40: =SUM(AC40+AD40) -> 7 | AF40: =COUNTIF(G40:AA40,"F") -> 2 | AG40: =IFERROR(AVERAGE(F40,K40,P40,U40,Z40),"-") -> 5.6666667
B41: Pierre Paulo | C41: P | D41: 0 | E41: 0 | H41: P | I41: 2 | J41: 1 | K41: 5 | M41: P | N41: 0 | O41: 0 | P41: 5.44 | R41: P | S41: 0 | T41: 1 | U41: 4.94 | AB41: =COUNTIF(C41:Z41,"P") -> 4 | AC41: =SUM(D41,I41,N41,S41,X41) -> 2 | AD41: =SUM(E41,J41,O41,T41,Y41) -> 2 | AE41: =SUM(AC41+AD41) -> 4 | AF41: =COUNTIF(G41:AA41,"F") -> 0 | AG41: =IFERROR(AVERAGE(F41,K41,P41,U41,Z41),"-") -> 5.1266667
...

Sheet FEV
B1: PELADA DA RESENHA - TERÇA 20H
B3: JOGADOR | C3: 45692 | H3: =C3+7 -> 45699 | M3: =H3+7 -> 45706 | R3: =M3+7 -> 45713 | W3: - | AB3: PRESENÇA | AC3: GOLS TOTAIS | AD3: ASSIST TOTAIS | AE3: G+A | AG3: MÉDIA TOTAL
C4: PRESENTE | D4: GOL | E4: ASSIST | F4: NOTA | H4: PRESENTE | I4: GOL | J4: ASSIST | K4: NOTA | M4: PRESENTE | N4: GOL | O4: ASSIST | P4: NOTA | R4: PRESENTE | S4: GOL | T4: ASSIST | U4: NOTA | W4: PRESENTE | X4: GOL | Y4: ASSIST | Z4: NOTA
B5: Alberto Henrique | C5: P | D5: 1 | E5: 0 | F5: 5.16 | H5: P | I5: 1 | J5: 4 | K5: 5.54 | R5: P | S5: 1 | T5: 1 | U5: 6.34 | W5: - | X5: - | Y5: - | Z5: - | AB5: =COUNTIF(C5:Z5,"P") -> 3 | AC5: =SUM(D5,I5,N5,S5,X5) -> 3 | AD5: =SUM(E5,J5,O5,T5,Y5) -> 5 | AE5: =SUM(AC5+AD5) -> 8 | AF5: =COUNTIF(G5:AA5,"F") -> 0 | AG5: =IFERROR(AVERAGE(F5,K5,P5,U5,Z5),"-") -> 5.68
B6: Allan Borela | C6: P | D6: 0 | E6: 0 | F6: 4.64 | H6: P | I6: 1 | J6: 1 | K6: 5.38 | L6: F | M6: P | N6: 0 | O6: 1 | P6: 5.1 | Q6: F | R6: P | S6: 0 | T6: 0 | U6: 5.26 | W6: - | X6: - | Y6: - | Z6: - | AB6: =COUNTIF(C6:Z6,"P") -> 4 | AC6: =SUM(D6,I6,N6,S6,X6) -> 1 | AD6: =SUM(E6,J6,O6,T6,Y6) -> 2 | AE6: =SUM(AC6+AD6) -> 3 | AF6: =COUNTIF(G6:AA6,"F") -> 2 | AG6: =IFERROR(AVERAGE(F6,K6,P6,U6,Z6),"-") -> 5.095
B7: Breno (GK) | V7: F | W7: - | X7: - | Y7: - | Z7: - | AB7: =COUNTIF(C7:Z7,"P") -> 0 | AC7: =SUM(D7,I7,N7,S7,X7) -> 0 | AD7: =SUM(E7,J7,O7,T7,Y7) -> 0 | AE7: =SUM(AC7+AD7) -> 0 | AF7: =COUNTIF(G7:AA7,"F") -> 1 | AG7: =IFERROR(AVERAGE(F7,K7,P7,U7,Z7),"-") -> -
B8: Daniel Medeiros (GK) | W8: - | X8: - | Y8: - | Z8: - | AB8: =COUNTIF(C8:Z8,"P") -> 0 | AC8: =SUM(D8,I8,N8,S8,X8) -> 0 | AD8: =SUM(E8,J8,O8,T8,Y8) -> 0 | AE8: =SUM(AC8+AD8) -> 0 | AF8: =COUNTIF(G8:AA8,"F") -> 0 | AG8: =IFERROR(AVERAGE(F8,K8,P8,U8,Z8),"-") -> -
B9: David Melo | M9: P | N9: 0 | O9: 0 | P9: 4.96 | R9: P | S9: 1 | T9: 0 | U9: 5.96 | W9: - | X9: - | Y9: - | Z9: - | AB9: =COUNTIF(C9:Z9,"P") -> 2 | AC9: =SUM(D9,I9,N9,S9,X9) -> 1 | AD9: =SUM(E9,J9,O9,T9,Y9) -> 0 | AE9: =SUM(AC9+AD9) -> 1 | AF9: =COUNTIF(G9:AA9,"F") -> 0 | AG9: =IFERROR(AVERAGE(F9,K9,P9,U9,Z9),"-") -> 5.46
B10: Douglas DG (GK) | H10: P | I10: 0 | J10: 0 | K10: 6 | W10: - | X10: - | Y10: - | Z10: - | AB10: =COUNTIF(C10:Z10,"P") -> 1 | AC10: =SUM(D10,I10,N10,S10,X10) -> 0 | AD10: =SUM(E10,J10,O10,T10,Y10) -> 0 | AE10: =SUM(AC10+AD10) -> 0 | AF10: =COUNTIF(G10:AA10,"F") -> 0 | AG10: =IFERROR(AVERAGE(F10,K10,P10,U10,Z10),"-") -> 6
B11: Felipe Horsts | M11: P | N11: 5 | O11: 3 | P11: 6.04 | Q11: F | W11: - | X11: - | Y11: - | Z11: - | AB11: =COUNTIF(C11:Z11,"P") -> 1 | AC11: =SUM(D11,I11,N11,S11,X11) -> 5 | AD11: =SUM(E11,J11,O11,T11,Y11) -> 3 | AE11: =SUM(AC11+AD11) -> 8 | AF11: =COUNTIF(G11:AA11,"F") -> 1 | AG11: =IFERROR(AVERAGE(F11,K11,P11,U11,Z11),"-") -> 6.04
B12: Gabriel Andrade | C12: P | D12: 0 | E12: 2 | F12: 7.72 | G12: F | H12: P | I12: 2 | J12: 2 | K12: 7.62 | L12: F | M12: P | N12: 4 | O12: 2 | P12: 7.46 | R12: P | S12: 3 | T12: 2 | U12: 8.26 | V12: F | W12: - | X12: - | Y12: - | Z12: - | AB12: =COUNTIF(C12:Z12,"P") -> 4 | AC12: =SUM(D12,I12,N12,S12,X12) -> 9 | AD12: =SUM(E12,J12,O12,T12,Y12) -> 8 | AE12: =SUM(AC12+AD12) -> 17 | AF12: =COUNTIF(G12:AA12,"F") -> 3 | AG12: =IFERROR(AVERAGE(F12,K12,P12,U12,Z12),"-") -> 7.765
B13: Gabriel Castro | C13: P | D13: 0 | E13: 2 | F13: 4.22 | H13: P | I13: 3 | J13: 1 | K13: 5.66 | M13: P | N13: 0 | O13: 1 | P13: 4.6 | R13: P | S13: 0 | T13: 1 | U13: 4.96 | W13: - | X13: - | Y13: - | Z13: - | AB13: =COUNTIF(C13:Z13,"P") -> 4 | AC13: =SUM(D13,I13,N13,S13,X13) -> 3 | AD13: =SUM(E13,J13,O13,T13,Y13) -> 5 | AE13: =SUM(AC13+AD13) -> 8 | AF13: =COUNTIF(G13:AA13,"F") -> 0 | AG13: =IFERROR(AVERAGE(F13,K13,P13,U13,Z13),"-") -> 4.86
B14: Gabriel Cosendey | W14: - | X14: - | Y14: - | Z14: - | AB14: =COUNTIF(C14:Z14,"P") -> 0 | AC14: =SUM(D14,I14,N14,S14,X14) -> 0 | AD14: =SUM(E14,J14,O14,T14,Y14) -> 0 | AE14: =SUM(AC14+AD14) -> 0 | AF14: =COUNTIF(G14:AA14,"F") -> 0 | AG14: =IFERROR(AVERAGE(F14,K14,P14,U14,Z14),"-") -> -
B15: Gabriel Teixeira | AB15: =COUNTIF(C15:Z15,"P") -> 0 | AC15: =SUM(D15,I15,N15,S15,X15) -> 0 | AD15: =SUM(E15,J15,O15,T15,Y15) -> 0 | AE15: =SUM(AC15+AD15) -> 0 | AF15: =COUNTIF(G15:AA15,"F") -> 0 | AG15: =IFERROR(AVERAGE(F15,K15,P15,U15,Z15),"-") -> -
B16: Guilherme Santos (GK) | C16: P | D16: 0 | E16: 0 | F16: 6.46 | G16: F | H16: P | I16: 0 | J16: 0 | K16: 6.8 | L16: F | M16: P | N16: 0 | O16: 0 | P16: 5.1 | R16: P | S16: 0 | T16: 0 | U16: 6.8 | W16: - | X16: - | Y16: - | Z16: - | AB16: =COUNTIF(C16:Z16,"P") -> 4 | AC16: =SUM(D16,I16,N16,S16,X16) -> 0 | AD16: =SUM(E16,J16,O16,T16,Y16) -> 0 | AE16: =SUM(AC16+AD16) -> 0 | AF16: =COUNTIF(G16:AA16,"F") -> 2 | AG16: =IFERROR(AVERAGE(F16,K16,P16,U16,Z16),"-") -> 6.29
B17: Gustavo Bumbum (GK) | W17: - | X17: - | Y17: - | Z17: - | AB17: =COUNTIF(C17:Z17,"P") -> 0 | AC17: =SUM(D17,I17,N17,S17,X17) -> 0 | AD17: =SUM(E17,J17,O17,T17,Y17) -> 0 | AE17: =SUM(AC17+AD17) -> 0 | AF17: =COUNTIF(G17:AA17,"F") -> 0 | AG17: =IFERROR(AVERAGE(F17,K17,P17,U17,Z17),"-") -> -
B18: Gustavo Gomes | W18: - | X18: - | Y18: - | Z18: - | AB18: =COUNTIF(C18:Z18,"P") -> 0 | AC18: =SUM(D18,I18,N18,S18,X18) -> 0 | AD18: =SUM(E18,J18,O18,T18,Y18) -> 0 | AE18: =SUM(AC18+AD18) -> 0 | AF18: =COUNTIF(G18:AA18,"F") -> 0 | AG18: =IFERROR(AVERAGE(F18,K18,P18,U18,Z18),"-") -> -
B19: Henrique Viza | H19: P | I19: 3 | J19: 3 | K19: 7.7 | L19: F | M19: P | N19: 5 | O19: 1 | P19: 8.1 | Q19: F | R19: P | S19: 6 | T19: 0 | U19: 9.54 | W19: - | X19: - | Y19: - | Z19: - | AB19: =COUNTIF(C19:Z19,"P") -> 3 | AC19: =SUM(D19,I19,N19,S19,X19) -> 14 | AD19: =SUM(E19,J19,O19,T19,Y19) -> 4 | AE19: =SUM(AC19+AD19) -> 18 | AF19: =COUNTIF(G19:AA19,"F") -> 2 | AG19: =IFERROR(AVERAGE(F19,K19,P19,U19,Z19),"-") -> 8.4466667
B20: Jeferson Neves | AB20: =COUNTIF(C20:Z20,"P") -> 0 | AC20: =SUM(D20,I20,N20,S20,X20) -> 0 | AD20: =SUM(E20,J20,O20,T20,Y20) -> 0 | AE20: =SUM(AC20+AD20) -> 0 | AF20: =COUNTIF(G20:AA20,"F") -> 0 | AG20: =IFERROR(AVERAGE(F20,K20,P20,U20,Z20),"-") -> -
B21: João Victor - Bazim | C21: P | D21: 0 | E21: 0 | F21: 4.64 | M21: P | N21: 0 | O21: 0 | P21: 4.96 | R21: P | S21: 0 | T21: 0 | U21: 5.54 | W21: - | X21: - | Y21: - | Z21: - | AB21: =COUNTIF(C21:Z21,"P") -> 3 | AC21: =SUM(D21,I21,N21,S21,X21) -> 0 | AD21: =SUM(E21,J21,O21,T21,Y21) -> 0 | AE21: =SUM(AC21+AD21) -> 0 | AF21: =COUNTIF(G21:AA21,"F") -> 0 | AG21: =IFERROR(AVERAGE(F21,K21,P21,U21,Z21),"-") -> 5.0466667
B22: João Vitor Nunes | C22: P | D22: 3 | E22: 0 | F22: 5.54 | G22: F | H22: P | I22: 3 | J22: 0 | K22: 4.92 | M22: P | N22: 4 | O22: 0 | P22: 5.18 | R22: P | S22: 2 | T22: 0 | U22: 4.42 | W22: - | X22: - | Y22: - | Z22: - | AB22: =COUNTIF(C22:Z22,"P") -> 4 | AC22: =SUM(D22,I22,N22,S22,X22) -> 12 | AD22: =SUM(E22,J22,O22,T22,Y22) -> 0 | AE22: =SUM(AC22+AD22) -> 12 | AF22: =COUNTIF(G22:AA22,"F") -> 1 | AG22: =IFERROR(AVERAGE(F22,K22,P22,U22,Z22),"-") -> 5.015
B23: José Guilherme | W23: - | X23: - | Y23: - | Z23: - | AB23: =COUNTIF(C23:Z23,"P") -> 0 | AC23: =SUM(D23,I23,N23,S23,X23) -> 0 | AD23: =SUM(E23,J23,O23,T23,Y23) -> 0 | AE23: =SUM(AC23+AD23) -> 0 | AF23: =COUNTIF(G23:AA23,"F") -> 0 | AG23: =IFERROR(AVERAGE(F23,K23,P23,U23,Z23),"-") -> -
B24: Kyrius Barros | C24: P | D24: 1 | E24: 0 | F24: 5.52 | G24: F | H24: P | I24: 3 | J24: 0 | K24: 4.92 | W24: - | X24: - | Y24: - | Z24: - | AB24: =COUNTIF(C24:Z24,"P") -> 2 | AC24: =SUM(D24,I24,N24,S24,X24) -> 4 | AD24: =SUM(E24,J24,O24,T24,Y24) -> 0 | AE24: =SUM(AC24+AD24) -> 4 | AF24: =COUNTIF(G24:AA24,"F") -> 1 | AG24: =IFERROR(AVERAGE(F24,K24,P24,U24,Z24),"-") -> 5.22
B25: Leo Bitencourt | W25: - | X25: - | Y25: - | Z25: - | AB25: =COUNTIF(C25:Z25,"P") -> 0 | AC25: =SUM(D25,I25,N25,S25,X25) -> 0 | AD25: =SUM(E25,J25,O25,T25,Y25) -> 0 | AE25: =SUM(AC25+AD25) -> 0 | AF25: =COUNTIF(G25:AA25,"F") -> 0 | AG25: =IFERROR(AVERAGE(F25,K25,P25,U25,Z25),"-") -> -
B26: Leo Hubner | W26: - | X26: - | Y26: - | Z26: - | AB26: =COUNTIF(C26:Z26,"P") -> 0 | AC26: =SUM(D26,I26,N26,S26,X26) -> 0 | AD26: =SUM(E26,J26,O26,T26,Y26) -> 0 | AE26: =SUM(AC26+AD26) -> 0 | AF26: =COUNTIF(G26:AA26,"F") -> 0 | AG26: =IFERROR(AVERAGE(F26,K26,P26,U26,Z26),"-") -> -
B27: Leo Starling | C27: P | D27: 1 | E27: 0 | F27: 4.96 | H27: P | I27: 2 | J27: 0 | K27: 5.58 | M27: P | N27: 2 | O27: 1 | P27: 5.85 | R27: P | S27: 0 | T27: 0 | U27: 4.46 | W27: - | X27: - | Y27: - | Z27: - | AB27: =COUNTIF(C27:Z27,"P") -> 4 | AC27: =SUM(D27,I27,N27,S27,X27) -> 5 | AD27: =SUM(E27,J27,O27,T27,Y27) -> 1 | AE27: =SUM(AC27+AD27) -> 6 | AF27: =COUNTIF(G27:AA27,"F") -> 0 | AG27: =IFERROR(AVERAGE(F27,K27,P27,U27,Z27),"-") -> 5.2125
B28: Lucas Bertolace | AB28: =COUNTIF(C28:Z28,"P") -> 0 | AC28: =SUM(D28,I28,N28,S28,X28) -> 0 | AD28: =SUM(E28,J28,O28,T28,Y28) -> 0 | AE28: =SUM(AC28+AD28) -> 0 | AF28: =COUNTIF(G28:AA28,"F") -> 0 | AG28: =IFERROR(AVERAGE(F28,K28,P28,U28,Z28),"-") -> -
B29: Lucas Borela | W29: - | X29: - | Y29: - | Z29: - | AB29: =COUNTIF(C29:Z29,"P") -> 0 | AC29: =SUM(D29,I29,N29,S29,X29) -> 0 | AD29: =SUM(E29,J29,O29,T29,Y29) -> 0 | AE29: =SUM(AC29+AD29) -> 0 | AF29: =COUNTIF(G29:AA29,"F") -> 0 | AG29: =IFERROR(AVERAGE(F29,K29,P29,U29,Z29),"-") -> -
B30: Lucas Gama - Passarim | W30: - | X30: - | Y30: - | Z30: - | AB30: =COUNTIF(C30:Z30,"P") -> 0 | AC30: =SUM(D30,I30,N30,S30,X30) -> 0 | AD30: =SUM(E30,J30,O30,T30,Y30) -> 0 | AE30: =SUM(AC30+AD30) -> 0 | AF30: =COUNTIF(G30:AA30,"F") -> 0 | AG30: =IFERROR(AVERAGE(F30,K30,P30,U30,Z30),"-") -> -
B31: Lucas Leite - Coxinha | M31: P | N31: 2 | O31: 3 | P31: 5.6 | R31: P | S31: 0 | T31: 1 | U31: 5.88 | W31: - | X31: - | Y31: - | Z31: - | AB31: =COUNTIF(C31:Z31,"P") -> 2 | AC31: =SUM(D31,I31,N31,S31,X31) -> 2 | AD31: =SUM(E31,J31,O31,T31,Y31) -> 4 | AE31: =SUM(AC31+AD31) -> 6 | AF31: =COUNTIF(G31:AA31,"F") -> 0 | AG31: =IFERROR(AVERAGE(F31,K31,P31,U31,Z31),"-") -> 5.74
B32: Luis do Corte | AB32: =COUNTIF(C32:Z32,"P") -> 0 | AC32: =SUM(D32,I32,N32,S32,X32) -> 0 | AD32: =SUM(E32,J32,O32,T32,Y32) -> 0 | AE32: =SUM(AC32+AD32) -> 0 | AF32: =COUNTIF(G32:AA32,"F") -> 0 | AG32: =IFERROR(AVERAGE(F32,K32,P32,U32,Z32),"-") -> -
B33: Marcelo Castro | C33: P | D33: 2 | E33: 2 | F33: 7.18 | H33: P | I33: 2 | J33: 0 | K33: 6.8 | W33: - | X33: - | Y33: - | Z33: - | AB33: =COUNTIF(C33:Z33,"P") -> 2 | AC33: =SUM(D33,I33,N33,S33,X33) -> 4 | AD33: =SUM(E33,J33,O33,T33,Y33) -> 2 | AE33: =SUM(AC33+AD33) -> 6 | AF33: =COUNTIF(G33:AA33,"F") -> 0 | AG33: =IFERROR(AVERAGE(F33,K33,P33,U33,Z33),"-") -> 6.99
B34: Marco Antonio | C34: P | D34: 0 | E34: 0 | F34: 5.14 | H34: P | I34: 0 | J34: 0 | K34: 4.88 | M34: P | N34: 0 | O34: 1 | W34: - | X34: - | Y34: - | Z34: - | AB34: =COUNTIF(C34:Z34,"P") -> 3 | AC34: =SUM(D34,I34,N34,S34,X34) -> 0 | AD34: =SUM(E34,J34,O34,T34,Y34) -> 1 | AE34: =SUM(AC34+AD34) -> 1 | AF34: =COUNTIF(G34:AA34,"F") -> 0 | AG34: =IFERROR(AVERAGE(F34,K34,P34,U34,Z34),"-") -> 5.01
B35: Matheus Gomes | C35: P | D35: 0 | E35: 3 | F35: 5.18 | G35: F | M35: P | N35: 5 | O35: 3 | Q35: F | R35: P | S35: 1 | T35: 0 | U35: 5.34 | W35: - | X35: - | Y35: - | Z35: - | AB35: =COUNTIF(C35:Z35,"P") -> 3 | AC35: =SUM(D35,I35,N35,S35,X35) -> 6 | AD35: =SUM(E35,J35,O35,T35,Y35) -> 6 | AE35: =SUM(AC35+AD35) -> 12 | AF35: =COUNTIF(G35:AA35,"F") -> 2 | AG35: =IFERROR(AVERAGE(F35,K35,P35,U35,Z35),"-") -> 5.26
B36: Meurin | H36: P | I36: 0 | J36: 1 | K36: 5.08 | M36: P | N36: 0 | O36: 1 | P36: 4.9 | R36: P | S36: 1 | T36: 4 | U36: 6.46 | W36: - | X36: - | Y36: - | Z36: - | AB36: =COUNTIF(C36:Z36,"P") -> 3 | AC36: =SUM(D36,I36,N36,S36,X36) -> 1 | AD36: =SUM(E36,J36,O36,T36,Y36) -> 6 | AE36: =SUM(AC36+AD36) -> 7 | AF36: =COUNTIF(G36:AA36,"F") -> 0 | AG36: =IFERROR(AVERAGE(F36,K36,P36,U36,Z36),"-") -> 5.48
B37: Pablo Brandão | C37: P | D37: 0 | E37: 0 | F37: 4.6 | H37: P | I37: 1 | J37: 1 | K37: 6.42 | L37: F | M37: P | N37: 1 | O37: 0 | P37: 4.54 | R37: P | S37: 0 | T37: 1 | U37: 5.66 | V37: F | W37: - | X37: - | Y37: - | Z37: - | AB37: =COUNTIF(C37:Z37,"P") -> 4 | AC37: =SUM(D37,I37,N37,S37,X37) -> 2 | AD37: =SUM(E37,J37,O37,T37,Y37) -> 2 | AE37: =SUM(AC37+AD37) -> 4 | AF37: =COUNTIF(G37:AA37,"F") -> 2 | AG37: =IFERROR(AVERAGE(F37,K37,P37,U37,Z37),"-") -> 5.305
B38: Pedro Abreu | W38: - | X38: - | Y38: - | Z38: - | AB38: =COUNTIF(C38:Z38,"P") -> 0 | AC38: =SUM(D38,I38,N38,S38,X38) -> 0 | AD38: =SUM(E38,J38,O38,T38,Y38) -> 0 | AE38: =SUM(AC38+AD38) -> 0 | AF38: =COUNTIF(G38:AA38,"F") -> 0 | AG38: =IFERROR(AVERAGE(F38,K38,P38,U38,Z38),"-") -> -
B39: Pedro Chequer | C39: P | D39: 0 | E39: 0 | F39: 5.18 | G39: F | H39: P | I39: 1 | J39: 0 | K39: 5.26 | M39: P | N39: 0 | O39: 1 | P39: 5.22 | R39: P | S39: 0 | T39: 0 | U39: 4.38 | W39: - | X39: - | Y39: - | Z39: - | AB39: =COUNTIF(C39:Z39,"P") -> 4 | AC39: =SUM(D39,I39,N39,S39,X39) -> 1 | AD39: =SUM(E39,J39,O39,T39,Y39) -> 1 | AE39: =SUM(AC39+AD39) -> 2 | AF39: =COUNTIF(G39:AA39,"F") -> 1 | AG39: =IFERROR(AVERAGE(F39,K39,P39,U39,Z39),"-") -> 5.01
B40: Pedro Dias | C40: P | D40: 0 | E40: 0 | F40: 7.04 | H40: P | I40: 1 | J40: 4 | K40: 6.34 | M40: P | N40: 2 | O40: 3 | P40: 6.6 | Q40: F | R40: P | S40: 2 | T40: 2 | U40: 5.7 | W40: - | X40: - | Y40: - | Z40: - | AB40: =COUNTIF(C40:Z40,"P") -> 4 | AC40: =SUM(D40,I40,N40,S40,X40) -> 5 | AD40: =SUM(E40,J40,O40,T40,Y40) -> 9 | AE40: =SUM(AC40+AD40) -> 14 | AF40: =COUNTIF(G40:AA40,"F") -> 1 | AG40: =IFERROR(AVERAGE(F40,K40,P40,U40,Z40),"-") -> 6.42
B41: Pierre Paulo | C41: P | D41: 0 | E41: 1 | F41: 5.5 | H41: P | I41: 1 | J41: 1 | K41: 6.42 | L41: F | M41: P | N41: 0 | O41: 2 | P41: 5.82 | R41: P | S41: 0 | T41: 0 | U41: 5.7 | V41: F | W41: - | X41: - | Y41: - | Z41: - | AB41: =COUNTIF(C41:Z41,"P") -> 4 | AC41: =SUM(D41,I41,N41,S41,X41) -> 1 | AD41: =SUM(E41,J41,O41,T41,Y41) -> 4 | AE41: =SUM(AC41+AD41) -> 5 | AF41: =COUNTIF(G41:AA41,"F") -> 2 | AG41: =IFERROR(AVERAGE(F41,K41,P41,U41,Z41),"-") -> 5.86
...

Sheet MAR
B1: PELADA DA RESENHA - TERÇA 20H
B3: JOGADOR | C3: 45720 | H3: =C3+7 -> 45727 | M3: =H3+7 -> 45734 | R3: =M3+7 -> 45741 | W3: - | AB3: PRESENÇA | AC3: GOLS TOTAIS | AD3: ASSIST TOTAIS | AE3: G+A | AG3: MÉDIA TOTAL
C4: PRESENTE | D4: GOL | E4: ASSIST | F4: NOTA | H4: PRESENTE | I4: GOL | J4: ASSIST | K4: NOTA | M4: PRESENTE | N4: GOL | O4: ASSIST | P4: NOTA | R4: PRESENTE | S4: GOL | T4: ASSIST | U4: NOTA | W4: PRESENTE | X4: GOL | Y4: ASSIST | Z4: NOTA
B5: Alberto Henrique | L5: F | M5: P | N5: 4 | O5: 2 | P5: 7.4 | Q5: F | W5: - | X5: - | Y5: - | Z5: - | AB5: =COUNTIF(C5:Z5,"P") -> 1 | AC5: =SUM(D5,I5,N5,S5,X5) -> 4 | AD5: =SUM(E5,J5,O5,T5,Y5) -> 2 | AE5: =SUM(AC5+AD5) -> 6 | AF5: =COUNTIF(G5:AA5,"F") -> 2 | AG5: =IFERROR(AVERAGE(F5,K5,P5,U5,Z5),"-") -> 7.4
B6: Allan Borela | C6: P | D6: 0 | E6: 0 | F6: 5 | G6: F | M6: P | N6: 0 | O6: 2 | P6: 6.34 | Q6: F | R6: P | S6: 1 | T6: 2 | U6: 5.94 | W6: - | X6: - | Y6: - | Z6: - | AB6: =COUNTIF(C6:Z6,"P") -> 3 | AC6: =SUM(D6,I6,N6,S6,X6) -> 1 | AD6: =SUM(E6,J6,O6,T6,Y6) -> 4 | AE6: =SUM(AC6+AD6) -> 5 | AF6: =COUNTIF(G6:AA6,"F") -> 2 | AG6: =IFERROR(AVERAGE(F6,K6,P6,U6,Z6),"-") -> 5.76
B7: Breno (GK) | C7: P | D7: 0 | E7: 0 | F7: 6.64 | G7: F | H7: P | I7: 0 | J7: 0 | K7: 6.4 | R7: P | S7: 0 | T7: 0 | U7: 7.8 | V7: F | W7: - | X7: - | Y7: - | Z7: - | AB7: =COUNTIF(C7:Z7,"P") -> 3 | AC7: =SUM(D7,I7,N7,S7,X7) -> 0 | AD7: =SUM(E7,J7,O7,T7,Y7) -> 0 | AE7: =SUM(AC7+AD7) -> 0 | AF7: =COUNTIF(G7:AA7,"F") -> 2 | AG7: =IFERROR(AVERAGE(F7,K7,P7,U7,Z7),"-") -> 6.9466667
B8: Daniel Medeiros (GK) | W8: - | X8: - | Y8: - | Z8: - | AB8: =COUNTIF(C8:Z8,"P") -> 0 | AC8: =SUM(D8,I8,N8,S8,X8) -> 0 | AD8: =SUM(E8,J8,O8,T8,Y8) -> 0 | AE8: =SUM(AC8+AD8) -> 0 | AF8: =COUNTIF(G8:AA8,"F") -> 0 | AG8: =IFERROR(AVERAGE(F8,K8,P8,U8,Z8),"-") -> -
B9: David Melo | H9: P | I9: 1 | J9: 0 | K9: 5.4 | M9: P | N9: 0 | O9: 0 | P9: 4.66 | W9: - | X9: - | Y9: - | Z9: - | AB9: =COUNTIF(C9:Z9,"P") -> 2 | AC9: =SUM(D9,I9,N9,S9,X9) -> 1 | AD9: =SUM(E9,J9,O9,T9,Y9) -> 0 | AE9: =SUM(AC9+AD9) -> 1 | AF9: =COUNTIF(G9:AA9,"F") -> 0 | AG9: =IFERROR(AVERAGE(F9,K9,P9,U9,Z9),"-") -> 5.03
B10: Douglas DG (GK) | W10: - | X10: - | Y10: - | Z10: - | AB10: =COUNTIF(C10:Z10,"P") -> 0 | AC10: =SUM(D10,I10,N10,S10,X10) -> 0 | AD10: =SUM(E10,J10,O10,T10,Y10) -> 0 | AE10: =SUM(AC10+AD10) -> 0 | AF10: =COUNTIF(G10:AA10,"F") -> 0 | AG10: =IFERROR(AVERAGE(F10,K10,P10,U10,Z10),"-") -> -
B11: Felipe Horsts | H11: P | I11: 3 | J11: 1 | K11: 7.48 | L11: F | M11: P | N11: 0 | O11: 0 | P11: 7.52 | Q11: F | W11: - | X11: - | Y11: - | Z11: - | AB11: =COUNTIF(C11:Z11,"P") -> 2 | AC11: =SUM(D11,I11,N11,S11,X11) -> 3 | AD11: =SUM(E11,J11,O11,T11,Y11) -> 1 | AE11: =SUM(AC11+AD11) -> 4 | AF11: =COUNTIF(G11:AA11,"F") -> 2 | AG11: =IFERROR(AVERAGE(F11,K11,P11,U11,Z11),"-") -> 7.5
B12: Gabriel Andrade | H12: P | I12: 2 | J12: 0 | K12: 6.96 | M12: P | N12: 2 | O12: 2 | P12: 6.86 | W12: - | X12: - | Y12: - | Z12: - | AB12: =COUNTIF(C12:Z12,"P") -> 2 | AC12: =SUM(D12,I12,N12,S12,X12) -> 4 | AD12: =SUM(E12,J12,O12,T12,Y12) -> 2 | AE12: =SUM(AC12+AD12) -> 6 | AF12: =COUNTIF(G12:AA12,"F") -> 0 | AG12: =IFERROR(AVERAGE(F12,K12,P12,U12,Z12),"-") -> 6.91
B13: Gabriel Castro | C13: P | D13: 0 | E13: 1 | F13: 4 | H13: P | I13: 0 | J13: 1 | K13: 5.52 | R13: P | S13: 4 | T13: 0 | U13: 6.94 | W13: - | X13: - | Y13: - | Z13: - | AB13: =COUNTIF(C13:Z13,"P") -> 3 | AC13: =SUM(D13,I13,N13,S13,X13) -> 4 | AD13: =SUM(E13,J13,O13,T13,Y13) -> 2 | AE13: =SUM(AC13+AD13) -> 6 | AF13: =COUNTIF(G13:AA13,"F") -> 0 | AG13: =IFERROR(AVERAGE(F13,K13,P13,U13,Z13),"-") -> 5.4866667
B14: Gabriel Cosendey | H14: P | I14: 2 | J14: 0 | K14: 7 | W14: - | X14: - | Y14: - | Z14: - | AB14: =COUNTIF(C14:Z14,"P") -> 1 | AC14: =SUM(D14,I14,N14,S14,X14) -> 2 | AD14: =SUM(E14,J14,O14,T14,Y14) -> 0 | AE14: =SUM(AC14+AD14) -> 2 | AF14: =COUNTIF(G14:AA14,"F") -> 0 | AG14: =IFERROR(AVERAGE(F14,K14,P14,U14,Z14),"-") -> 7
B15: Gabriel Teixeira | AB15: =COUNTIF(C15:Z15,"P") -> 0 | AC15: =SUM(D15,I15,N15,S15,X15) -> 0 | AD15: =SUM(E15,J15,O15,T15,Y15) -> 0 | AE15: =SUM(AC15+AD15) -> 0 | AF15: =COUNTIF(G15:AA15,"F") -> 0 | AG15: =IFERROR(AVERAGE(F15,K15,P15,U15,Z15),"-") -> -
B16: Guilherme Santos (GK) | C16: P | D16: 0 | E16: 0 | F16: 7 | H16: P | I16: 0 | J16: 0 | K16: 5.34 | M16: P | N16: 0 | O16: 0 | P16: 5.1 | R16: P | S16: 0 | T16: 2 | U16: 6.78 | W16: - | X16: - | Y16: - | Z16: - | AB16: =COUNTIF(C16:Z16,"P") -> 4 | AC16: =SUM(D16,I16,N16,S16,X16) -> 0 | AD16: =SUM(E16,J16,O16,T16,Y16) -> 2 | AE16: =SUM(AC16+AD16) -> 2 | AF16: =COUNTIF(G16:AA16,"F") -> 0 | AG16: =IFERROR(AVERAGE(F16,K16,P16,U16,Z16),"-") -> 6.055
B17: Gustavo Bumbum (GK) | C17: P | D17: 0 | E17: 0 | F17: 6.14 | W17: - | X17: - | Y17: - | Z17: - | AB17: =COUNTIF(C17:Z17,"P") -> 1 | AC17: =SUM(D17,I17,N17,S17,X17) -> 0 | AD17: =SUM(E17,J17,O17,T17,Y17) -> 0 | AE17: =SUM(AC17+AD17) -> 0 | AF17: =COUNTIF(G17:AA17,"F") -> 0 | AG17: =IFERROR(AVERAGE(F17,K17,P17,U17,Z17),"-") -> 6.14
B18: Gustavo Gomes | W18: - | X18: - | Y18: - | Z18: - | AB18: =COUNTIF(C18:Z18,"P") -> 0 | AC18: =SUM(D18,I18,N18,S18,X18) -> 0 | AD18: =SUM(E18,J18,O18,T18,Y18) -> 0 | AE18: =SUM(AC18+AD18) -> 0 | AF18: =COUNTIF(G18:AA18,"F") -> 0 | AG18: =IFERROR(AVERAGE(F18,K18,P18,U18,Z18),"-") -> -
B19: Henrique Viza | H19: P | I19: 1 | J19: 0 | K19: 6.66 | M19: P | N19: 3 | O19: 0 | P19: 5.86 | V19: F | W19: - | X19: - | Y19: - | Z19: - | AB19: =COUNTIF(C19:Z19,"P") -> 2 | AC19: =SUM(D19,I19,N19,S19,X19) -> 4 | AD19: =SUM(E19,J19,O19,T19,Y19) -> 0 | AE19: =SUM(AC19+AD19) -> 4 | AF19: =COUNTIF(G19:AA19,"F") -> 1 | AG19: =IFERROR(AVERAGE(F19,K19,P19,U19,Z19),"-") -> 6.26
B20: Jeferson Neves | AB20: =COUNTIF(C20:Z20,"P") -> 0 | AC20: =SUM(D20,I20,N20,S20,X20) -> 0 | AD20: =SUM(E20,J20,O20,T20,Y20) -> 0 | AE20: =SUM(AC20+AD20) -> 0 | AF20: =COUNTIF(G20:AA20,"F") -> 0 | AG20: =IFERROR(AVERAGE(F20,K20,P20,U20,Z20),"-") -> -
B21: João Victor - Bazim | M21: P | N21: 1 | O21: 1 | P21: 6.48 | Q21: F | R21: P | S21: 1 | T21: 1 | U21: 4.84 | W21: - | X21: - | Y21: - | Z21: - | AB21: =COUNTIF(C21:Z21,"P") -> 2 | AC21: =SUM(D21,I21,N21,S21,X21) -> 2 | AD21: =SUM(E21,J21,O21,T21,Y21) -> 2 | AE21: =SUM(AC21+AD21) -> 4 | AF21: =COUNTIF(G21:AA21,"F") -> 1 | AG21: =IFERROR(AVERAGE(F21,K21,P21,U21,Z21),"-") -> 5.66
B22: João Vitor Nunes | C22: P | D22: 1 | E22: 0 | F22: 4.38 | H22: P | I22: 1 | J22: 0 | K22: 4.96 | M22: P | N22: 2 | O22: 1 | P22: 4.78 | R22: P | S22: 1 | T22: 2 | U22: 4.94 | V22: F | W22: - | X22: - | Y22: - | Z22: - | AB22: =COUNTIF(C22:Z22,"P") -> 4 | AC22: =SUM(D22,I22,N22,S22,X22) -> 5 | AD22: =SUM(E22,J22,O22,T22,Y22) -> 3 | AE22: =SUM(AC22+AD22) -> 8 | AF22: =COUNTIF(G22:AA22,"F") -> 1 | AG22: =IFERROR(AVERAGE(F22,K22,P22,U22,Z22),"-") -> 4.765
B23: José Guilherme | W23: - | X23: - | Y23: - | Z23: - | AB23: =COUNTIF(C23:Z23,"P") -> 0 | AC23: =SUM(D23,I23,N23,S23,X23) -> 0 | AD23: =SUM(E23,J23,O23,T23,Y23) -> 0 | AE23: =SUM(AC23+AD23) -> 0 | AF23: =COUNTIF(G23:AA23,"F") -> 0 | AG23: =IFERROR(AVERAGE(F23,K23,P23,U23,Z23),"-") -> -
B24: Kyrius Barros | C24: P | D24: 2 | E24: 0 | F24: 6.36 | M24: P | N24: 0 | O24: 1 | P24: 2.84 | W24: - | X24: - | Y24: - | Z24: - | AB24: =COUNTIF(C24:Z24,"P") -> 2 | AC24: =SUM(D24,I24,N24,S24,X24) -> 2 | AD24: =SUM(E24,J24,O24,T24,Y24) -> 1 | AE24: =SUM(AC24+AD24) -> 3 | AF24: =COUNTIF(G24:AA24,"F") -> 0 | AG24: =IFERROR(AVERAGE(F24,K24,P24,U24,Z24),"-") -> 4.6
B25: Leo Bitencourt | W25: - | X25: - | Y25: - | Z25: - | AB25: =COUNTIF(C25:Z25,"P") -> 0 | AC25: =SUM(D25,I25,N25,S25,X25) -> 0 | AD25: =SUM(E25,J25,O25,T25,Y25) -> 0 | AE25: =SUM(AC25+AD25) -> 0 | AF25: =COUNTIF(G25:AA25,"F") -> 0 | AG25: =IFERROR(AVERAGE(F25,K25,P25,U25,Z25),"-") -> -
B26: Leo Hubner | W26: - | X26: - | Y26: - | Z26: - | AB26: =COUNTIF(C26:Z26,"P") -> 0 | AC26: =SUM(D26,I26,N26,S26,X26) -> 0 | AD26: =SUM(E26,J26,O26,T26,Y26) -> 0 | AE26: =SUM(AC26+AD26) -> 0 | AF26: =COUNTIF(G26:AA26,"F") -> 0 | AG26: =IFERROR(AVERAGE(F26,K26,P26,U26,Z26),"-") -> -
B27: Leo Starling | H27: P | I27: 2 | J27: 1 | K27: 6.4 | L27: F | M27: P | N27: 0 | O27: 0 | P27: 4.12 | W27: - | X27: - | Y27: - | Z27: - | AB27: =COUNTIF(C27:Z27,"P") -> 2 | AC27: =SUM(D27,I27,N27,S27,X27) -> 2 | AD27: =SUM(E27,J27,O27,T27,Y27) -> 1 | AE27: =SUM(AC27+AD27) -> 3 | AF27: =COUNTIF(G27:AA27,"F") -> 1 | AG27: =IFERROR(AVERAGE(F27,K27,P27,U27,Z27),"-") -> 5.26
B28: Lucas Bertolace | AB28: =COUNTIF(C28:Z28,"P") -> 0 | AC28: =SUM(D28,I28,N28,S28,X28) -> 0 | AD28: =SUM(E28,J28,O28,T28,Y28) -> 0 | AE28: =SUM(AC28+AD28) -> 0 | AF28: =COUNTIF(G28:AA28,"F") -> 0 | AG28: =IFERROR(AVERAGE(F28,K28,P28,U28,Z28),"-") -> -
B29: Lucas Borela | R29: P | S29: 0 | T29: 2 | U29: 4.06 | W29: - | X29: - | Y29: - | Z29: - | AB29: =COUNTIF(C29:Z29,"P") -> 1 | AC29: =SUM(D29,I29,N29,S29,X29) -> 0 | AD29: =SUM(E29,J29,O29,T29,Y29) -> 2 | AE29: =SUM(AC29+AD29) -> 2 | AF29: =COUNTIF(G29:AA29,"F") -> 0 | AG29: =IFERROR(AVERAGE(F29,K29,P29,U29,Z29),"-") -> 4.06
B30: Lucas Gama - Passarim | W30: - | X30: - | Y30: - | Z30: - | AB30: =COUNTIF(C30:Z30,"P") -> 0 | AC30: =SUM(D30,I30,N30,S30,X30) -> 0 | AD30: =SUM(E30,J30,O30,T30,Y30) -> 0 | AE30: =SUM(AC30+AD30) -> 0 | AF30: =COUNTIF(G30:AA30,"F") -> 0 | AG30: =IFERROR(AVERAGE(F30,K30,P30,U30,Z30),"-") -> -
B31: Lucas Leite - Coxinha | C31: P | D31: 1 | E31: 0 | F31: 5.16 | H31: P | I31: 1 | J31: 0 | K31: 5.78 | M31: P | N31: 0 | O31: 0 | P31: 4.92 | R31: P | S31: 1 | T31: 0 | U31: 4.48 | W31: - | X31: - | Y31: - | Z31: - | AB31: =COUNTIF(C31:Z31,"P") -> 4 | AC31: =SUM(D31,I31,N31,S31,X31) -> 3 | AD31: =SUM(E31,J31,O31,T31,Y31) -> 0 | AE31: =SUM(AC31+AD31) -> 3 | AF31: =COUNTIF(G31:AA31,"F") -> 0 | AG31: =IFERROR(AVERAGE(F31,K31,P31,U31,Z31),"-") -> 5.085
B32: Luis do Corte | AB32: =COUNTIF(C32:Z32,"P") -> 0 | AC32: =SUM(D32,I32,N32,S32,X32) -> 0 | AD32: =SUM(E32,J32,O32,T32,Y32) -> 0 | AE32: =SUM(AC32+AD32) -> 0 | AF32: =COUNTIF(G32:AA32,"F") -> 0 | AG32: =IFERROR(AVERAGE(F32,K32,P32,U32,Z32),"-") -> -
B33: Marcelo Castro | W33: - | X33: - | Y33: - | Z33: - | AB33: =COUNTIF(C33:Z33,"P") -> 0 | AC33: =SUM(D33,I33,N33,S33,X33) -> 0 | AD33: =SUM(E33,J33,O33,T33,Y33) -> 0 | AE33: =SUM(AC33+AD33) -> 0 | AF33: =COUNTIF(G33:AA33,"F") -> 0 | AG33: =IFERROR(AVERAGE(F33,K33,P33,U33,Z33),"-") -> -
B34: Marco Antonio | H34: P | I34: 0 | J34: 0 | K34: 5.22 | M34: P | N34: 0 | O34: 0 | P34: 5 | R34: P | S34: 2 | T34: 1 | U34: 5.94 | V34: F | W34: - | X34: - | Y34: - | Z34: - | AB34: =COUNTIF(C34:Z34,"P") -> 3 | AC34: =SUM(D34,I34,N34,S34,X34) -> 2 | AD34: =SUM(E34,J34,O34,T34,Y34) -> 1 | AE34: =SUM(AC34+AD34) -> 3 | AF34: =COUNTIF(G34:AA34,"F") -> 1 | AG34: =IFERROR(AVERAGE(F34,K34,P34,U34,Z34),"-") -> 5.3866667
B35: Matheus Gomes | C35: P | D35: 4 | E35: 1 | F35: 6.7 | G35: F | H35: P | I35: 1 | J35: 0 | K35: 5.14 | M35: P | N35: 1 | O35: 1 | P35: 3.48 | R35: P | S35: 5 | T35: 1 | U35: 6.78 | W35: - | X35: - | Y35: - | Z35: - | AB35: =COUNTIF(C35:Z35,"P") -> 4 | AC35: =SUM(D35,I35,N35,S35,X35) -> 11 | AD35: =SUM(E35,J35,O35,T35,Y35) -> 3 | AE35: =SUM(AC35+AD35) -> 14 | AF35: =COUNTIF(G35:AA35,"F") -> 1 | AG35: =IFERROR(AVERAGE(F35,K35,P35,U35,Z35),"-") -> 5.525
B36: Meurin | H36: P | I36: 2 | J36: 1 | K36: 8.34 | L36: F | M36: P | N36: 0 | O36: 2 | P36: 4.7 | R36: P | S36: 2 | T36: 1 | U36: 6.32 | V36: F | W36: - | X36: - | Y36: - | Z36: - | AB36: =COUNTIF(C36:Z36,"P") -> 3 | AC36: =SUM(D36,I36,N36,S36,X36) -> 4 | AD36: =SUM(E36,J36,O36,T36,Y36) -> 4 | AE36: =SUM(AC36+AD36) -> 8 | AF36: =COUNTIF(G36:AA36,"F") -> 2 | AG36: =IFERROR(AVERAGE(F36,K36,P36,U36,Z36),"-") -> 6.4533333
B37: Pablo Brandão | C37: P | D37: 0 | E37: 0 | F37: 4.84 | H37: P | I37: 0 | J37: 0 | K37: 5.04 | M37: P | N37: 0 | O37: 1 | P37: 5.66 | R37: P | S37: 0 | T37: 0 | U37: 4.94 | W37: - | X37: - | Y37: - | Z37: - | AB37: =COUNTIF(C37:Z37,"P") -> 4 | AC37: =SUM(D37,I37,N37,S37,X37) -> 0 | AD37: =SUM(E37,J37,O37,T37,Y37) -> 1 | AE37: =SUM(AC37+AD37) -> 1 | AF37: =COUNTIF(G37:AA37,"F") -> 0 | AG37: =IFERROR(AVERAGE(F37,K37,P37,U37,Z37),"-") -> 5.12
B38: Pedro Abreu | W38: - | X38: - | Y38: - | Z38: - | AB38: =COUNTIF(C38:Z38,"P") -> 0 | AC38: =SUM(D38,I38,N38,S38,X38) -> 0 | AD38: =SUM(E38,J38,O38,T38,Y38) -> 0 | AE38: =SUM(AC38+AD38) -> 0 | AF38: =COUNTIF(G38:AA38,"F") -> 0 | AG38: =IFERROR(AVERAGE(F38,K38,P38,U38,Z38),"-") -> -
B39: Pedro Chequer | C39: P | D39: 0 | E39: 0 | F39: 5 | R39: P | S39: 0 | T39: 0 | U39: 5.06 | V39: F | W39: - | X39: - | Y39: - | Z39: - | AB39: =COUNTIF(C39:Z39,"P") -> 2 | AC39: =SUM(D39,I39,N39,S39,X39) -> 0 | AD39: =SUM(E39,J39,O39,T39,Y39) -> 0 | AE39: =SUM(AC39+AD39) -> 0 | AF39: =COUNTIF(G39:AA39,"F") -> 1 | AG39: =IFERROR(AVERAGE(F39,K39,P39,U39,Z39),"-") -> 5.03
B40: Pedro Dias | C40: P | D40: 2 | E40: 3 | F40: 7.08 | H40: P | I40: 0 | J40: 2 | K40: 6.3 | M40: P | N40: 1 | O40: 0 | P40: 5.92 | R40: P | S40: 1 | T40: 1 | U40: 5 | W40: - | X40: - | Y40: - | Z40: - | AB40: =COUNTIF(C40:Z40,"P") -> 4 | AC40: =SUM(D40,I40,N40,S40,X40) -> 4 | AD40: =SUM(E40,J40,O40,T40,Y40) -> 6 | AE40: =SUM(AC40+AD40) -> 10 | AF40: =COUNTIF(G40:AA40,"F") -> 0 | AG40: =IFERROR(AVERAGE(F40,K40,P40,U40,Z40),"-") -> 6.075
B41: Pierre Paulo | C41: P | D41: 1 | E41: 1 | F41: 5.76 | H41: P | I41: 1 | J41: 1 | K41: 6.04 | M41: P | N41: 1 | O41: 1 | P41: 6.44 | Q41: F | R41: P | S41: 1 | T41: 0 | U41: 6 | V41: F | W41: - | X41: - | Y41: - | Z41: - | AB41: =COUNTIF(C41:Z41,"P") -> 4 | AC41: =SUM(D41,I41,N41,S41,X41) -> 4 | AD41: =SUM(E41,J41,O41,T41,Y41) -> 3 | AE41: =SUM(AC41+AD41) -> 7 | AF41: =COUNTIF(G41:AA41,"F") -> 2 | AG41: =IFERROR(AVERAGE(F41,K41,P41,U41,Z41),"-") -> 6.06
...

Sheet ABR
B1: PELADA DA RESENHA - TERÇA 20H
B3: JOGADOR | C3: 45748 | H3: =C3+7 -> 45755 | M3: =H3+7 -> 45762 | R3: =M3+7 -> 45769 | W3: =R3+7 -> 45776 | AB3: PRESENÇA | AC3: GOLS TOTAIS | AD3: ASSIST TOTAIS | AE3: G+A | AG3: MÉDIA TOTAL
C4: PRESENTE | D4: GOL | E4: ASSIST | F4: NOTA | H4: PRESENTE | I4: GOL | J4: ASSIST | K4: NOTA | M4: PRESENTE | N4: GOL | O4: ASSIST | P4: NOTA | R4: PRESENTE | S4: GOL | T4: ASSIST | U4: NOTA | W4: PRESENTE | X4: GOL | Y4: ASSIST | Z4: NOTA
B5: Alberto Henrique | C5: P | D5: 0 | E5: 0 | F5: 6.18 | H5: P | I5: 4 | J5: 0 | K5: 5.92 | W5: P | X5: 4 | Y5: 2 | Z5: 6.66 | AA5: F | AB5: =COUNTIF(C5:Z5,"P") -> 3 | AC5: =SUM(D5,I5,N5,S5,X5) -> 8 | AD5: =SUM(E5,J5,O5,T5,Y5) -> 2 | AE5: =SUM(AC5+AD5) -> 10 | AF5: =COUNTIF(G5:AA5,"F") -> 1 | AG5: =IFERROR(AVERAGE(F5,K5,P5,U5,Z5),"-") -> 6.2533333
B6: Allan Borela | C6: P | D6: 0 | E6: 0 | F6: 5.42 | G6: F | AB6: =COUNTIF(C6:Z6,"P") -> 1 | AC6: =SUM(D6,I6,N6,S6,X6) -> 0 | AD6: =SUM(E6,J6,O6,T6,Y6) -> 0 | AE6: =SUM(AC6+AD6) -> 0 | AF6: =COUNTIF(G6:AA6,"F") -> 1 | AG6: =IFERROR(AVERAGE(F6,K6,P6,U6,Z6),"-") -> 5.42
B7: Breno (GK) | AB7: =COUNTIF(C7:Z7,"P") -> 0 | AC7: =SUM(D7,I7,N7,S7,X7) -> 0 | AD7: =SUM(E7,J7,O7,T7,Y7) -> 0 | AE7: =SUM(AC7+AD7) -> 0 | AF7: =COUNTIF(G7:AA7,"F") -> 0 | AG7: =IFERROR(AVERAGE(F7,K7,P7,U7,Z7),"-") -> -
B8: Daniel Medeiros (GK) | C8: P | D8: 0 | E8: 0 | F8: 4.84 | AB8: =COUNTIF(C8:Z8,"P") -> 1 | AC8: =SUM(D8,I8,N8,S8,X8) -> 0 | AD8: =SUM(E8,J8,O8,T8,Y8) -> 0 | AE8: =SUM(AC8+AD8) -> 0 | AF8: =COUNTIF(G8:AA8,"F") -> 0 | AG8: =IFERROR(AVERAGE(F8,K8,P8,U8,Z8),"-") -> 4.84
B9: David Melo | H9: P | I9: 2 | J9: 1 | K9: 5.64 | M9: P | N9: 3 | O9: 4 | P9: 6.06 | AB9: =COUNTIF(C9:Z9,"P") -> 2 | AC9: =SUM(D9,I9,N9,S9,X9) -> 5 | AD9: =SUM(E9,J9,O9,T9,Y9) -> 5 | AE9: =SUM(AC9+AD9) -> 10 | AF9: =COUNTIF(G9:AA9,"F") -> 0 | AG9: =IFERROR(AVERAGE(F9,K9,P9,U9,Z9),"-") -> 5.85
B10: Douglas DG (GK) | H10: P | I10: 0 | J10: 0 | K10: 6.4 | L10: F | R10: P | S10: 0 | T10: 0 | U10: 8.28 | V10: F | W10: P | X10: 0 | Y10: 0 | Z10: 8.06 | AA10: F | AB10: =COUNTIF(C10:Z10,"P") -> 3 | AC10: =SUM(D10,I10,N10,S10,X10) -> 0 | AD10: =SUM(E10,J10,O10,T10,Y10) -> 0 | AE10: =SUM(AC10+AD10) -> 0 | AF10: =COUNTIF(G10:AA10,"F") -> 3 | AG10: =IFERROR(AVERAGE(F10,K10,P10,U10,Z10),"-") -> 7.58
B11: Felipe Horsts | AB11: =COUNTIF(C11:Z11,"P") -> 0 | AC11: =SUM(D11,I11,N11,S11,X11) -> 0 | AD11: =SUM(E11,J11,O11,T11,Y11) -> 0 | AE11: =SUM(AC11+AD11) -> 0 | AF11: =COUNTIF(G11:AA11,"F") -> 0 | AG11: =IFERROR(AVERAGE(F11,K11,P11,U11,Z11),"-") -> -
B12: Gabriel Andrade | C12: P | D12: 1 | E12: 3 | F12: 6.76 | H12: P | I12: 3 | J12: 0 | K12: 6.92 | M12: P | N12: 2 | O12: 2 | P12: 7.12 | R12: P | S12: 4 | T12: 0 | U12: 7.72 | V12: F | AB12: =COUNTIF(C12:Z12,"P") -> 4 | AC12: =SUM(D12,I12,N12,S12,X12) -> 10 | AD12: =SUM(E12,J12,O12,T12,Y12) -> 5 | AE12: =SUM(AC12+AD12) -> 15 | AF12: =COUNTIF(G12:AA12,"F") -> 1 | AG12: =IFERROR(AVERAGE(F12,K12,P12,U12,Z12),"-") -> 7.13
B13: Gabriel Castro | C13: P | D13: 3 | E13: 1 | F13: 5.48 | H13: P | I13: 2 | J13: 2 | K13: 6.22 | L13: F | M13: P | N13: 1 | O13: 0 | P13: 4.8 | R13: P | S13: 3 | T13: 1 | U13: 6.64 | V13: F | W13: P | X13: 1 | Y13: 1 | Z13: 5.94 | AA13: F | AB13: =COUNTIF(C13:Z13,"P") -> 5 | AC13: =SUM(D13,I13,N13,S13,X13) -> 10 | AD13: =SUM(E13,J13,O13,T13,Y13) -> 5 | AE13: =SUM(AC13+AD13) -> 15 | AF13: =COUNTIF(G13:AA13,"F") -> 3 | AG13: =IFERROR(AVERAGE(F13,K13,P13,U13,Z13),"-") -> 5.816
B14: Gabriel Cosendey | R14: P | S14: 0 | T14: 0 | U14: 5.64 | W14: P | X14: 0 | Y14: 1 | Z14: 5.54 | AB14: =COUNTIF(C14:Z14,"P") -> 2 | AC14: =SUM(D14,I14,N14,S14,X14) -> 0 | AD14: =SUM(E14,J14,O14,T14,Y14) -> 1 | AE14: =SUM(AC14+AD14) -> 1 | AF14: =COUNTIF(G14:AA14,"F") -> 0 | AG14: =IFERROR(AVERAGE(F14,K14,P14,U14,Z14),"-") -> 5.59
B15: Gabriel Teixeira | AB15: =COUNTIF(C15:Z15,"P") -> 0 | AC15: =SUM(D15,I15,N15,S15,X15) -> 0 | AD15: =SUM(E15,J15,O15,T15,Y15) -> 0 | AE15: =SUM(AC15+AD15) -> 0 | AF15: =COUNTIF(G15:AA15,"F") -> 0 | AG15: =IFERROR(AVERAGE(F15,K15,P15,U15,Z15),"-") -> -
B16: Guilherme Santos (GK) | C16: P | D16: 0 | E16: 0 | F16: 6.36 | G16: F | M16: P | N16: 0 | O16: 0 | P16: 6.46 | Q16: F | R16: P | S16: 0 | T16: 0 | U16: 7.28 | W16: P | X16: 0 | Y16: 0 | Z16: 6 | AB16: =COUNTIF(C16:Z16,"P") -> 4 | AC16: =SUM(D16,I16,N16,S16,X16) -> 0 | AD16: =SUM(E16,J16,O16,T16,Y16) -> 0 | AE16: =SUM(AC16+AD16) -> 0 | AF16: =COUNTIF(G16:AA16,"F") -> 2 | AG16: =IFERROR(AVERAGE(F16,K16,P16,U16,Z16),"-") -> 6.525
B17: Gustavo Bumbum (GK) | AB17: =COUNTIF(C17:Z17,"P") -> 0 | AC17: =SUM(D17,I17,N17,S17,X17) -> 0 | AD17: =SUM(E17,J17,O17,T17,Y17) -> 0 | AE17: =SUM(AC17+AD17) -> 0 | AF17: =COUNTIF(G17:AA17,"F") -> 0 | AG17: =IFERROR(AVERAGE(F17,K17,P17,U17,Z17),"-") -> -
B18: Gustavo Gomes | AB18: =COUNTIF(C18:Z18,"P") -> 0 | AC18: =SUM(D18,I18,N18,S18,X18) -> 0 | AD18: =SUM(E18,J18,O18,T18,Y18) -> 0 | AE18: =SUM(AC18+AD18) -> 0 | AF18: =COUNTIF(G18:AA18,"F") -> 0 | AG18: =IFERROR(AVERAGE(F18,K18,P18,U18,Z18),"-") -> -
B19: Henrique Viza | H19: P | I19: 4 | J19: 2 | K19: 6.78 | L19: F | AB19: =COUNTIF(C19:Z19,"P") -> 1 | AC19: =SUM(D19,I19,N19,S19,X19) -> 4 | AD19: =SUM(E19,J19,O19,T19,Y19) -> 2 | AE19: =SUM(AC19+AD19) -> 6 | AF19: =COUNTIF(G19:AA19,"F") -> 1 | AG19: =IFERROR(AVERAGE(F19,K19,P19,U19,Z19),"-") -> 6.78
B20: Jeferson Neves | AB20: =COUNTIF(C20:Z20,"P") -> 0 | AC20: =SUM(D20,I20,N20,S20,X20) -> 0 | AD20: =SUM(E20,J20,O20,T20,Y20) -> 0 | AE20: =SUM(AC20+AD20) -> 0 | AF20: =COUNTIF(G20:AA20,"F") -> 0 | AG20: =IFERROR(AVERAGE(F20,K20,P20,U20,Z20),"-") -> -
B21: João Victor - Bazim | C21: P | D21: 0 | E21: 1 | F21: 5.88 | W21: P | X21: 0 | Y21: 0 | Z21: 4.26 | AB21: =COUNTIF(C21:Z21,"P") -> 2 | AC21: =SUM(D21,I21,N21,S21,X21) -> 0 | AD21: =SUM(E21,J21,O21,T21,Y21) -> 1 | AE21: =SUM(AC21+AD21) -> 1 | AF21: =COUNTIF(G21:AA21,"F") -> 0 | AG21: =IFERROR(AVERAGE(F21,K21,P21,U21,Z21),"-") -> 5.07
B22: João Vitor Nunes | AB22: =COUNTIF(C22:Z22,"P") -> 0 | AC22: =SUM(D22,I22,N22,S22,X22) -> 0 | AD22: =SUM(E22,J22,O22,T22,Y22) -> 0 | AE22: =SUM(AC22+AD22) -> 0 | AF22: =COUNTIF(G22:AA22,"F") -> 0 | AG22: =IFERROR(AVERAGE(F22,K22,P22,U22,Z22),"-") -> -
B23: José Guilherme | H23: P | I23: 2 | J23: 2 | K23: 6.06 | L23: F | M23: P | N23: 6 | O23: 0 | P23: 8.38 | Q23: F | R23: P | S23: 1 | T23: 1 | U23: 5.64 | W23: P | X23: 1 | Y23: 3 | Z23: 5.66 | AB23: =COUNTIF(C23:Z23,"P") -> 4 | AC23: =SUM(D23,I23,N23,S23,X23) -> 10 | AD23: =SUM(E23,J23,O23,T23,Y23) -> 6 | AE23: =SUM(AC23+AD23) -> 16 | AF23: =COUNTIF(G23:AA23,"F") -> 2 | AG23: =IFERROR(AVERAGE(F23,K23,P23,U23,Z23),"-") -> 6.435
B24: Kyrius Barros | AB24: =COUNTIF(C24:Z24,"P") -> 0 | AC24: =SUM(D24,I24,N24,S24,X24) -> 0 | AD24: =SUM(E24,J24,O24,T24,Y24) -> 0 | AE24: =SUM(AC24+AD24) -> 0 | AF24: =COUNTIF(G24:AA24,"F") -> 0 | AG24: =IFERROR(AVERAGE(F24,K24,P24,U24,Z24),"-") -> -
B25: Leo Bitencourt | V25: F | AB25: =COUNTIF(C25:Z25,"P") -> 0 | AC25: =SUM(D25,I25,N25,S25,X25) -> 0 | AD25: =SUM(E25,J25,O25,T25,Y25) -> 0 | AE25: =SUM(AC25+AD25) -> 0 | AF25: =COUNTIF(G25:AA25,"F") -> 1 | AG25: =IFERROR(AVERAGE(F25,K25,P25,U25,Z25),"-") -> -
B26: Leo Hubner | AB26: =COUNTIF(C26:Z26,"P") -> 0 | AC26: =SUM(D26,I26,N26,S26,X26) -> 0 | AD26: =SUM(E26,J26,O26,T26,Y26) -> 0 | AE26: =SUM(AC26+AD26) -> 0 | AF26: =COUNTIF(G26:AA26,"F") -> 0 | AG26: =IFERROR(AVERAGE(F26,K26,P26,U26,Z26),"-") -> -
B27: Leo Starling | C27: P | D27: 2 | E27: 2 | F27: 6.48 | H27: P | I27: 3 | J27: 2 | K27: 5.58 | M27: P | N27: 0 | O27: 0 | P27: 4.18 | R27: P | S27: 0 | T27: 1 | U27: 6.14 | V27: F | AB27: =COUNTIF(C27:Z27,"P") -> 4 | AC27: =SUM(D27,I27,N27,S27,X27) -> 5 | AD27: =SUM(E27,J27,O27,T27,Y27) -> 5 | AE27: =SUM(AC27+AD27) -> 10 | AF27: =COUNTIF(G27:AA27,"F") -> 1 | AG27: =IFERROR(AVERAGE(F27,K27,P27,U27,Z27),"-") -> 5.595
B28: Lucas Bertolace | AB28: =COUNTIF(C28:Z28,"P") -> 0 | AC28: =SUM(D28,I28,N28,S28,X28) -> 0 | AD28: =SUM(E28,J28,O28,T28,Y28) -> 0 | AE28: =SUM(AC28+AD28) -> 0 | AF28: =COUNTIF(G28:AA28,"F") -> 0 | AG28: =IFERROR(AVERAGE(F28,K28,P28,U28,Z28),"-") -> -
B29: Lucas Borela | H29: P | I29: 0 | J29: 1 | K29: 3.46 | AB29: =COUNTIF(C29:Z29,"P") -> 1 | AC29: =SUM(D29,I29,N29,S29,X29) -> 0 | AD29: =SUM(E29,J29,O29,T29,Y29) -> 1 | AE29: =SUM(AC29+AD29) -> 1 | AF29: =COUNTIF(G29:AA29,"F") -> 0 | AG29: =IFERROR(AVERAGE(F29,K29,P29,U29,Z29),"-") -> 3.46
B30: Lucas Gama - Passarim | AB30: =COUNTIF(C30:Z30,"P") -> 0 | AC30: =SUM(D30,I30,N30,S30,X30) -> 0 | AD30: =SUM(E30,J30,O30,T30,Y30) -> 0 | AE30: =SUM(AC30+AD30) -> 0 | AF30: =COUNTIF(G30:AA30,"F") -> 0 | AG30: =IFERROR(AVERAGE(F30,K30,P30,U30,Z30),"-") -> -
B31: Lucas Leite - Coxinha | C31: P | D31: 1 | E31: 1 | F31: 5.64 | M31: P | N31: 0 | O31: 3 | P31: 6.38 | Q31: F | AB31: =COUNTIF(C31:Z31,"P") -> 2 | AC31: =SUM(D31,I31,N31,S31,X31) -> 1 | AD31: =SUM(E31,J31,O31,T31,Y31) -> 4 | AE31: =SUM(AC31+AD31) -> 5 | AF31: =COUNTIF(G31:AA31,"F") -> 1 | AG31: =IFERROR(AVERAGE(F31,K31,P31,U31,Z31),"-") -> 6.01
B32: Luis do Corte | AB32: =COUNTIF(C32:Z32,"P") -> 0 | AC32: =SUM(D32,I32,N32,S32,X32) -> 0 | AD32: =SUM(E32,J32,O32,T32,Y32) -> 0 | AE32: =SUM(AC32+AD32) -> 0 | AF32: =COUNTIF(G32:AA32,"F") -> 0 | AG32: =IFERROR(AVERAGE(F32,K32,P32,U32,Z32),"-") -> -
B33: Marcelo Castro | AB33: =COUNTIF(C33:Z33,"P") -> 0 | AC33: =SUM(D33,I33,N33,S33,X33) -> 0 | AD33: =SUM(E33,J33,O33,T33,Y33) -> 0 | AE33: =SUM(AC33+AD33) -> 0 | AF33: =COUNTIF(G33:AA33,"F") -> 0 | AG33: =IFERROR(AVERAGE(F33,K33,P33,U33,Z33),"-") -> -
B34: Marco Antonio | C34: P | D34: 0 | E34: 0 | F34: 6.42 | G34: F | H34: P | I34: 0 | J34: 1 | K34: 5.86 | L34: F | R34: P | S34: 1 | T34: 0 | U34: 6.08 | W34: P | X34: 0 | Y34: 0 | Z34: 6.14 | AA34: F | AB34: =COUNTIF(C34:Z34,"P") -> 4 | AC34: =SUM(D34,I34,N34,S34,X34) -> 1 | AD34: =SUM(E34,J34,O34,T34,Y34) -> 1 | AE34: =SUM(AC34+AD34) -> 2 | AF34: =COUNTIF(G34:AA34,"F") -> 3 | AG34: =IFERROR(AVERAGE(F34,K34,P34,U34,Z34),"-") -> 6.125
B35: Matheus Gomes | C35: P | D35: 4 | E35: 2 | F35: 7.52 | G35: F | W35: P | X35: 3 | Y35: 0 | Z35: 5.5 | AB35: =COUNTIF(C35:Z35,"P") -> 2 | AC35: =SUM(D35,I35,N35,S35,X35) -> 7 | AD35: =SUM(E35,J35,O35,T35,Y35) -> 2 | AE35: =SUM(AC35+AD35) -> 9 | AF35: =COUNTIF(G35:AA35,"F") -> 1 | AG35: =IFERROR(AVERAGE(F35,K35,P35,U35,Z35),"-") -> 6.51
B36: Meurin | C36: P | D36: 1 | E36: 0 | F36: 4.58 | H36: P | I36: 2 | J36: 4 | K36: 4.78 | M36: P | N36: 0 | O36: 0 | P36: 3.66 | R36: P | S36: 0 | T36: 3 | U36: 5.92 | V36: F | W36: P | X36: 1 | Y36: 2 | Z36: 6.32 | AA36: F | AB36: =COUNTIF(C36:Z36,"P") -> 5 | AC36: =SUM(D36,I36,N36,S36,X36) -> 4 | AD36: =SUM(E36,J36,O36,T36,Y36) -> 9 | AE36: =SUM(AC36+AD36) -> 13 | AF36: =COUNTIF(G36:AA36,"F") -> 2 | AG36: =IFERROR(AVERAGE(F36,K36,P36,U36,Z36),"-") -> 5.052
B37: Pablo Brandão | C37: P | D37: 0 | E37: 0 | F37: 5.7 | H37: P | I37: 0 | J37: 0 | K37: 5.64 | M37: P | N37: 0 | O37: 1 | P37: 5.62 | R37: P | S37: 0 | T37: 0 | U37: 5.86 | W37: P | X37: 1 | Y37: 1 | Z37: 7.34 | AA37: F | AB37: =COUNTIF(C37:Z37,"P") -> 5 | AC37: =SUM(D37,I37,N37,S37,X37) -> 1 | AD37: =SUM(E37,J37,O37,T37,Y37) -> 2 | AE37: =SUM(AC37+AD37) -> 3 | AF37: =COUNTIF(G37:AA37,"F") -> 1 | AG37: =IFERROR(AVERAGE(F37,K37,P37,U37,Z37),"-") -> 6.032
B38: Pedro Abreu | AB38: =COUNTIF(C38:Z38,"P") -> 0 | AC38: =SUM(D38,I38,N38,S38,X38) -> 0 | AD38: =SUM(E38,J38,O38,T38,Y38) -> 0 | AE38: =SUM(AC38+AD38) -> 0 | AF38: =COUNTIF(G38:AA38,"F") -> 0 | AG38: =IFERROR(AVERAGE(F38,K38,P38,U38,Z38),"-") -> -
B39: Pedro Chequer | M39: P | N39: 1 | O39: 0 | P39: 5.26 | W39: P | X39: 1 | Y39: 0 | Z39: 4.34 | AB39: =COUNTIF(C39:Z39,"P") -> 2 | AC39: =SUM(D39,I39,N39,S39,X39) -> 2 | AD39: =SUM(E39,J39,O39,T39,Y39) -> 0 | AE39: =SUM(AC39+AD39) -> 2 | AF39: =COUNTIF(G39:AA39,"F") -> 0 | AG39: =IFERROR(AVERAGE(F39,K39,P39,U39,Z39),"-") -> 4.8
B40: Pedro Dias | C40: P | D40: 6 | E40: 3 | F40: 8.88 | G40: F | H40: P | I40: 1 | J40: 0 | M40: P | N40: 1 | O40: 0 | P40: 4.32 | R40: P | S40: 2 | T40: 0 | U40: 5.5 | W40: P | X40: 1 | Y40: 2 | Z40: 5.4 | AB40: =COUNTIF(C40:Z40,"P") -> 5 | AC40: =SUM(D40,I40,N40,S40,X40) -> 11 | AD40: =SUM(E40,J40,O40,T40,Y40) -> 5 | AE40: =SUM(AC40+AD40) -> 16 | AF40: =COUNTIF(G40:AA40,"F") -> 1 | AG40: =IFERROR(AVERAGE(F40,K40,P40,U40,Z40),"-") -> 6.025
B41: Pierre Paulo | C41: P | D41: 0 | E41: 0 | F41: 5.7 | H41: P | I41: 0 | J41: 0 | K41: 5.92 | M41: P | N41: 1 | O41: 0 | P41: 5.12 | R41: P | S41: 0 | T41: 1 | U41: 5.78 | W41: P | X41: 0 | Y41: 1 | Z41: 6 | AB41: =COUNTIF(C41:Z41,"P") -> 5 | AC41: =SUM(D41,I41,N41,S41,X41) -> 1 | AD41: =SUM(E41,J41,O41,T41,Y41) -> 2 | AE41: =SUM(AC41+AD41) -> 3 | AF41: =COUNTIF(G41:AA41,"F") -> 0 | AG41: =IFERROR(AVERAGE(F41,K41,P41,U41,Z41),"-") -> 5.704
...

Sheet MAI
B1: PELADA DA RESENHA - TERÇA 20H
B3: JOGADOR | C3: 45783 | H3: =C3+7 -> 45790 | M3: =H3+7 -> 45797 | R3: =M3+7 -> 45804 | W3: - | AB3: PRESENÇA | AC3: GOLS TOTAIS | AD3: ASSIST TOTAIS | AE3: G+A | AG3: MÉDIA TOTAL
C4: PRESENTE | D4: GOL | E4: ASSIST | F4: NOTA | H4: PRESENTE | I4: GOL | J4: ASSIST | K4: NOTA | M4: PRESENTE | N4: GOL | O4: ASSIST | P4: NOTA | R4: PRESENTE | S4: GOL | T4: ASSIST | U4: NOTA | W4: PRESENTE | X4: GOL | Y4: ASSIST | Z4: NOTA
B5: Alberto Henrique | C5: P | D5: 2 | E5: 0 | F5: 5.38 | G5: F | H5: P | I5: 2 | J5: 0 | K5: 6.06 | M5: P | N5: 0 | O5: 2 | P5: 6.62 | W5: - | X5: - | Y5: - | Z5: - | AB5: =COUNTIF(C5:Z5,"P") -> 3 | AC5: =SUM(D5,I5,N5,S5,X5) -> 4 | AD5: =SUM(E5,J5,O5,T5,Y5) -> 2 | AE5: =SUM(AC5+AD5) -> 6 | AF5: =COUNTIF(G5:AA5,"F") -> 1 | AG5: =IFERROR(AVERAGE(F5,K5,P5,U5,Z5),"-") -> 6.02
B6: Allan Borela | W6: - | X6: - | Y6: - | Z6: - | AB6: =COUNTIF(C6:Z6,"P") -> 0 | AC6: =SUM(D6,I6,N6,S6,X6) -> 0 | AD6: =SUM(E6,J6,O6,T6,Y6) -> 0 | AE6: =SUM(AC6+AD6) -> 0 | AF6: =COUNTIF(G6:AA6,"F") -> 0 | AG6: =IFERROR(AVERAGE(F6,K6,P6,U6,Z6),"-") -> -
B7: Breno (GK) | W7: - | X7: - | Y7: - | Z7: - | AB7: =COUNTIF(C7:Z7,"P") -> 0 | AC7: =SUM(D7,I7,N7,S7,X7) -> 0 | AD7: =SUM(E7,J7,O7,T7,Y7) -> 0 | AE7: =SUM(AC7+AD7) -> 0 | AF7: =COUNTIF(G7:AA7,"F") -> 0 | AG7: =IFERROR(AVERAGE(F7,K7,P7,U7,Z7),"-") -> -
B8: Daniel Medeiros (GK) | W8: - | X8: - | Y8: - | Z8: - | AB8: =COUNTIF(C8:Z8,"P") -> 0 | AC8: =SUM(D8,I8,N8,S8,X8) -> 0 | AD8: =SUM(E8,J8,O8,T8,Y8) -> 0 | AE8: =SUM(AC8+AD8) -> 0 | AF8: =COUNTIF(G8:AA8,"F") -> 0 | AG8: =IFERROR(AVERAGE(F8,K8,P8,U8,Z8),"-") -> -
B9: David Melo | C9: P | D9: 0 | E9: 0 | F9: 5.58 | G9: F | W9: - | X9: - | Y9: - | Z9: - | AB9: =COUNTIF(C9:Z9,"P") -> 1 | AC9: =SUM(D9,I9,N9,S9,X9) -> 0 | AD9: =SUM(E9,J9,O9,T9,Y9) -> 0 | AE9: =SUM(AC9+AD9) -> 0 | AF9: =COUNTIF(G9:AA9,"F") -> 1 | AG9: =IFERROR(AVERAGE(F9,K9,P9,U9,Z9),"-") -> 5.58
B10: Douglas DG (GK) | C10: P | D10: 0 | E10: 0 | F10: 6.72 | H10: P | I10: 0 | J10: 0 | K10: 6.42 | L10: F | M10: P | N10: 0 | O10: 0 | P10: 3.34 | R10: P | S10: 0 | T10: 0 | U10: 3.48 | W10: - | X10: - | Y10: - | Z10: - | AB10: =COUNTIF(C10:Z10,"P") -> 4 | AC10: =SUM(D10,I10,N10,S10,X10) -> 0 | AD10: =SUM(E10,J10,O10,T10,Y10) -> 0 | AE10: =SUM(AC10+AD10) -> 0 | AF10: =COUNTIF(G10:AA10,"F") -> 1 | AG10: =IFERROR(AVERAGE(F10,K10,P10,U10,Z10),"-") -> 4.99
B11: Felipe Horsts | W11: - | X11: - | Y11: - | Z11: - | AB11: =COUNTIF(C11:Z11,"P") -> 0 | AC11: =SUM(D11,I11,N11,S11,X11) -> 0 | AD11: =SUM(E11,J11,O11,T11,Y11) -> 0 | AE11: =SUM(AC11+AD11) -> 0 | AF11: =COUNTIF(G11:AA11,"F") -> 0 | AG11: =IFERROR(AVERAGE(F11,K11,P11,U11,Z11),"-") -> -
B12: Gabriel Andrade | C12: P | D12: 6 | E12: 0 | F12: 7.36 | G12: F | H12: P | I12: 2 | J12: 1 | K12: 6.64 | L12: F | M12: P | N12: 2 | O12: 0 | P12: 6.04 | R12: P | S12: 2 | T12: 2 | U12: 6.97 | V12: F | W12: - | X12: - | Y12: - | Z12: - | AB12: =COUNTIF(C12:Z12,"P") -> 4 | AC12: =SUM(D12,I12,N12,S12,X12) -> 12 | AD12: =SUM(E12,J12,O12,T12,Y12) -> 3 | AE12: =SUM(AC12+AD12) -> 15 | AF12: =COUNTIF(G12:AA12,"F") -> 3 | AG12: =IFERROR(AVERAGE(F12,K12,P12,U12,Z12),"-") -> 6.7525
B13: Gabriel Castro | C13: P | D13: 0 | E13: 1 | F13: 4.48 | H13: P | I13: 0 | J13: 1 | K13: 5.64 | L13: F | M13: P | N13: 0 | O13: 2 | P13: 4.16 | R13: P | S13: 2 | T13: 0 | U13: 4.24 | W13: - | X13: - | Y13: - | Z13: - | AB13: =COUNTIF(C13:Z13,"P") -> 4 | AC13: =SUM(D13,I13,N13,S13,X13) -> 2 | AD13: =SUM(E13,J13,O13,T13,Y13) -> 4 | AE13: =SUM(AC13+AD13) -> 6 | AF13: =COUNTIF(G13:AA13,"F") -> 1 | AG13: =IFERROR(AVERAGE(F13,K13,P13,U13,Z13),"-") -> 4.63
B14: Gabriel Cosendey | C14: P | D14: 0 | E14: 0 | F14: 6.64 | W14: - | X14: - | Y14: - | Z14: - | AB14: =COUNTIF(C14:Z14,"P") -> 1 | AC14: =SUM(D14,I14,N14,S14,X14) -> 0 | AD14: =SUM(E14,J14,O14,T14,Y14) -> 0 | AE14: =SUM(AC14+AD14) -> 0 | AF14: =COUNTIF(G14:AA14,"F") -> 0 | AG14: =IFERROR(AVERAGE(F14,K14,P14,U14,Z14),"-") -> 6.64
B15: Gabriel Teixeira | AB15: =COUNTIF(C15:Z15,"P") -> 0 | AC15: =SUM(D15,I15,N15,S15,X15) -> 0 | AD15: =SUM(E15,J15,O15,T15,Y15) -> 0 | AE15: =SUM(AC15+AD15) -> 0 | AF15: =COUNTIF(G15:AA15,"F") -> 0 | AG15: =IFERROR(AVERAGE(F15,K15,P15,U15,Z15),"-") -> -
B16: Guilherme Santos (GK) | C16: P | D16: 0 | E16: 0 | F16: 6.62 | G16: F | H16: P | I16: 0 | J16: 0 | K16: 6.82 | M16: P | N16: 0 | O16: 0 | P16: 6.04 | R16: P | S16: 0 | T16: 0 | U16: 6.06 | V16: F | W16: - | X16: - | Y16: - | Z16: - | AB16: =COUNTIF(C16:Z16,"P") -> 4 | AC16: =SUM(D16,I16,N16,S16,X16) -> 0 | AD16: =SUM(E16,J16,O16,T16,Y16) -> 0 | AE16: =SUM(AC16+AD16) -> 0 | AF16: =COUNTIF(G16:AA16,"F") -> 2 | AG16: =IFERROR(AVERAGE(F16,K16,P16,U16,Z16),"-") -> 6.385
B17: Gustavo Bumbum (GK) | M17: P | N17: 0 | O17: 0 | P17: 5.68 | W17: - | X17: - | Y17: - | Z17: - | AB17: =COUNTIF(C17:Z17,"P") -> 1 | AC17: =SUM(D17,I17,N17,S17,X17) -> 0 | AD17: =SUM(E17,J17,O17,T17,Y17) -> 0 | AE17: =SUM(AC17+AD17) -> 0 | AF17: =COUNTIF(G17:AA17,"F") -> 0 | AG17: =IFERROR(AVERAGE(F17,K17,P17,U17,Z17),"-") -> 5.68
B18: Gustavo Gomes | W18: - | X18: - | Y18: - | Z18: - | AB18: =COUNTIF(C18:Z18,"P") -> 0 | AC18: =SUM(D18,I18,N18,S18,X18) -> 0 | AD18: =SUM(E18,J18,O18,T18,Y18) -> 0 | AE18: =SUM(AC18+AD18) -> 0 | AF18: =COUNTIF(G18:AA18,"F") -> 0 | AG18: =IFERROR(AVERAGE(F18,K18,P18,U18,Z18),"-") -> -
B19: Henrique Viza | M19: P | N19: 4 | O19: 2 | P19: 7.46 | Q19: F | R19: P | S19: 2 | T19: 1 | U19: 5.88 | W19: - | X19: - | Y19: - | Z19: - | AB19: =COUNTIF(C19:Z19,"P") -> 2 | AC19: =SUM(D19,I19,N19,S19,X19) -> 6 | AD19: =SUM(E19,J19,O19,T19,Y19) -> 3 | AE19: =SUM(AC19+AD19) -> 9 | AF19: =COUNTIF(G19:AA19,"F") -> 1 | AG19: =IFERROR(AVERAGE(F19,K19,P19,U19,Z19),"-") -> 6.67
B20: Jeferson Neves | AB20: =COUNTIF(C20:Z20,"P") -> 0 | AC20: =SUM(D20,I20,N20,S20,X20) -> 0 | AD20: =SUM(E20,J20,O20,T20,Y20) -> 0 | AE20: =SUM(AC20+AD20) -> 0 | AF20: =COUNTIF(G20:AA20,"F") -> 0 | AG20: =IFERROR(AVERAGE(F20,K20,P20,U20,Z20),"-") -> -
B21: João Victor - Bazim | C21: P | D21: 0 | E21: 0 | F21: 5.28 | G21: F | H21: P | I21: 0 | J21: 0 | K21: 5.5 | M21: P | N21: 2 | O21: 0 | P21: 5.66 | R21: P | S21: 1 | T21: 1 | U21: 5.62 | V21: F | W21: - | X21: - | Y21: - | Z21: - | AB21: =COUNTIF(C21:Z21,"P") -> 4 | AC21: =SUM(D21,I21,N21,S21,X21) -> 3 | AD21: =SUM(E21,J21,O21,T21,Y21) -> 1 | AE21: =SUM(AC21+AD21) -> 4 | AF21: =COUNTIF(G21:AA21,"F") -> 2 | AG21: =IFERROR(AVERAGE(F21,K21,P21,U21,Z21),"-") -> 5.515
B22: João Vitor Nunes | C22: P | D22: 2 | E22: 2 | F22: 4.64 | H22: P | I22: 2 | J22: 2 | K22: 4.82 | M22: P | N22: 3 | O22: 1 | P22: 4.76 | R22: P | S22: 2 | T22: 3 | U22: 5.56 | V22: F | W22: - | X22: - | Y22: - | Z22: - | AB22: =COUNTIF(C22:Z22,"P") -> 4 | AC22: =SUM(D22,I22,N22,S22,X22) -> 9 | AD22: =SUM(E22,J22,O22,T22,Y22) -> 8 | AE22: =SUM(AC22+AD22) -> 17 | AF22: =COUNTIF(G22:AA22,"F") -> 1 | AG22: =IFERROR(AVERAGE(F22,K22,P22,U22,Z22),"-") -> 4.945
B23: José Guilherme | C23: P | D23: 5 | E23: 3 | F23: 7.42 | H23: P | I23: 1 | J23: 1 | K23: 5.42 | M23: P | N23: 2 | O23: 0 | P23: 4.62 | R23: P | S23: 2 | T23: 0 | U23: 4.7 | W23: - | X23: - | Y23: - | Z23: - | AB23: =COUNTIF(C23:Z23,"P") -> 4 | AC23: =SUM(D23,I23,N23,S23,X23) -> 10 | AD23: =SUM(E23,J23,O23,T23,Y23) -> 4 | AE23: =SUM(AC23+AD23) -> 14 | AF23: =COUNTIF(G23:AA23,"F") -> 0 | AG23: =IFERROR(AVERAGE(F23,K23,P23,U23,Z23),"-") -> 5.54
B24: Kyrius Barros | W24: - | X24: - | Y24: - | Z24: - | AB24: =COUNTIF(C24:Z24,"P") -> 0 | AC24: =SUM(D24,I24,N24,S24,X24) -> 0 | AD24: =SUM(E24,J24,O24,T24,Y24) -> 0 | AE24: =SUM(AC24+AD24) -> 0 | AF24: =COUNTIF(G24:AA24,"F") -> 0 | AG24: =IFERROR(AVERAGE(F24,K24,P24,U24,Z24),"-") -> -
